# SYNTHETIC DATA - message format mirrors Coinbase Advanced WS; prices/sizes are invented
{"channel": "subscriptions", "client_id": "", "timestamp": "2026-09-24T12:00:00Z", "sequence_num": 0, "events": [{"subscriptions": {"level2": ["BTC-USD"], "market_trades": ["BTC-USD"]}}]}
{"channel": "l2_data", "client_id": "", "timestamp": "2026-09-24T12:00:00.100000Z", "sequence_num": 1, "events": [{"type": "snapshot", "product_id": "BTC-USD", "updates": [{"side": "bid", "event_time": "2026-09-24T12:00:00Z", "price_level": "64000.00", "new_quantity": "0.05000000"}, {"side": "offer", "event_time": "2026-09-24T12:00:00Z", "price_level": "64000.01", "new_quantity": "0.05000000"}, {"side": "bid", "event_time": "2026-09-24T12:00:00Z", "price_level": "63999.50", "new_quantity": "0.07000000"}, {"side": "offer", "event_time": "2026-09-24T12:00:00Z", "price_level": "64000.51", "new_quantity": "0.07000000"}, {"side": "bid", "event_time": "2026-09-24T12:00:00Z", "price_level": "63999.00", "new_quantity": "0.09000000"}, {"side": "offer", "event_time": "2026-09-24T12:00:00Z", "price_level": "64001.01", "new_quantity": "0.09000000"}, {"side": "bid", "event_time": "2026-09-24T12:00:00Z", "price_level": "63998.50", "new_quantity": "0.11000000"}, {"side": "offer", "event_time": "2026-09-24T12:00:00Z", "price_level": "64001.51", "new_quantity": "0.11000000"}, {"side": "bid", "event_time": "2026-09-24T12:00:00Z", "price_level": "63998.00", "new_quantity": "0.13000000"}, {"side": "offer", "event_time": "2026-09-24T12:00:00Z", "price_level": "64002.01", "new_quantity": "0.13000000"}, {"side": "bid", "event_time": "2026-09-24T12:00:00Z", "price_level": "63997.50", "new_quantity": "0.15000000"}, {"side": "offer", "event_time": "2026-09-24T12:00:00Z", "price_level": "64002.51", "new_quantity": "0.15000000"}, {"side": "bid", "event_time": "2026-09-24T12:00:00Z", "price_level": "63997.00", "new_quantity": "0.17000000"}, {"side": "offer", "event_time": "2026-09-24T12:00:00Z", "price_level": "64003.01", "new_quantity": "0.17000000"}, {"side": "bid", "event_time": "2026-09-24T12:00:00Z", "price_level": "63996.50", "new_quantity": "0.19000000"}, {"side": "offer", "event_time": "2026-09-24T12:00:00Z", "price_level": "64003.51", "new_quantity": "0.19000000"}, {"side": "bid", "event_time": "2026-09-24T12:00:00Z", "price_level": "63996.00", "new_quantity": "0.21000000"}, {"side": "offer", "event_time": "2026-09-24T12:00:00Z", "price_level": "64004.01", "new_quantity": "0.21000000"}, {"side": "bid", "event_time": "2026-09-24T12:00:00Z", "price_level": "63995.50", "new_quantity": "0.23000000"}, {"side": "offer", "event_time": "2026-09-24T12:00:00Z", "price_level": "64004.51", "new_quantity": "0.23000000"}]}]}
{"channel": "l2_data", "client_id": "", "timestamp": "2026-09-24T12:00:00.600000Z", "sequence_num": 2, "events": [{"type": "update", "product_id": "BTC-USD", "updates": [{"side": "bid", "event_time": "2026-09-24T12:00:00.600000Z", "price_level": "64000.00", "new_quantity": "0.06000000"}, {"side": "offer", "event_time": "2026-09-24T12:00:00.600000Z", "price_level": "64000.01", "new_quantity": "0.07000000"}]}]}
{"channel": "l2_data", "client_id": "", "timestamp": "2026-09-24T12:00:01.100000Z", "sequence_num": 3, "events": [{"type": "update", "product_id": "BTC-USD", "updates": [{"side": "bid", "event_time": "2026-09-24T12:00:01.100000Z", "price_level": "64000.00", "new_quantity": "0.06000000"}, {"side": "offer", "event_time": "2026-09-24T12:00:01.100000Z", "price_level": "64000.01", "new_quantity": "0.07000000"}]}]}
{"channel": "market_trades", "client_id": "", "timestamp": "2026-09-24T12:00:01.110000Z", "sequence_num": 4, "events": [{"type": "update", "trades": [{"trade_id": "1002", "product_id": "BTC-USD", "price": "64000.01", "size": "0.01500000", "side": "BUY", "time": "2026-09-24T12:00:01.110000Z"}]}]}
{"channel": "l2_data", "client_id": "", "timestamp": "2026-09-24T12:00:01.600000Z", "sequence_num": 5, "events": [{"type": "update", "product_id": "BTC-USD", "updates": [{"side": "bid", "event_time": "2026-09-24T12:00:01.600000Z", "price_level": "64000.00", "new_quantity": "0.06000000"}, {"side": "offer", "event_time": "2026-09-24T12:00:01.600000Z", "price_level": "64000.01", "new_quantity": "0.07000000"}]}]}
{"channel": "l2_data", "client_id": "", "timestamp": "2026-09-24T12:00:02.100000Z", "sequence_num": 6, "events": [{"type": "update", "product_id": "BTC-USD", "updates": [{"side": "bid", "event_time": "2026-09-24T12:00:02.100000Z", "price_level": "64000.00", "new_quantity": "0.06000000"}, {"side": "offer", "event_time": "2026-09-24T12:00:02.100000Z", "price_level": "64000.01", "new_quantity": "0.07000000"}]}]}
{"channel": "market_trades", "client_id": "", "timestamp": "2026-09-24T12:00:02.110000Z", "sequence_num": 7, "events": [{"type": "update", "trades": [{"trade_id": "1004", "product_id": "BTC-USD", "price": "64000.01", "size": "0.01500000", "side": "BUY", "time": "2026-09-24T12:00:02.110000Z"}]}]}
{"channel": "ticker", "client_id": "", "timestamp": "2026-09-24T12:00:02.120000Z", "sequence_num": 8, "events": [{"type": "update", "tickers": [{"type": "ticker", "product_id": "BTC-USD", "price": "64000.00", "best_bid": "64000.00", "best_bid_quantity": "0.06", "best_ask": "64000.01", "best_ask_quantity": "0.07"}]}]}
{"channel": "l2_data", "client_id": "", "timestamp": "2026-09-24T12:00:02.600000Z", "sequence_num": 9, "events": [{"type": "update", "product_id": "BTC-USD", "updates": [{"side": "bid", "event_time": "2026-09-24T12:00:02.600000Z", "price_level": "64000.00", "new_quantity": "0.06000000"}, {"side": "offer", "event_time": "2026-09-24T12:00:02.600000Z", "price_level": "64000.01", "new_quantity": "0.07000000"}]}]}
{"channel": "l2_data", "client_id": "", "timestamp": "2026-09-24T12:00:03.100000Z", "sequence_num": 10, "events": [{"type": "update", "product_id": "BTC-USD", "updates": [{"side": "bid", "event_time": "2026-09-24T12:00:03.100000Z", "price_level": "64000.00", "new_quantity": "0.06000000"}, {"side": "offer", "event_time": "2026-09-24T12:00:03.100000Z", "price_level": "64000.01", "new_quantity": "0.07000000"}]}]}
{"channel": "market_trades", "client_id": "", "timestamp": "2026-09-24T12:00:03.110000Z", "sequence_num": 11, "events": [{"type": "update", "trades": [{"trade_id": "1006", "product_id": "BTC-USD", "price": "64000.01", "size": "0.01500000", "side": "BUY", "time": "2026-09-24T12:00:03.110000Z"}]}]}
{"channel": "l2_data", "client_id": "", "timestamp": "2026-09-24T12:00:03.600000Z", "sequence_num": 12, "events": [{"type": "update", "product_id": "BTC-USD", "updates": [{"side": "bid", "event_time": "2026-09-24T12:00:03.600000Z", "price_level": "64000.00", "new_quantity": "0.06000000"}, {"side": "offer", "event_time": "2026-09-24T12:00:03.600000Z", "price_level": "64000.01", "new_quantity": "0.07000000"}]}]}
{"channel": "l2_data", "client_id": "", "timestamp": "2026-09-24T12:00:04.100000Z", "sequence_num": 13, "events": [{"type": "update", "product_id": "BTC-USD", "updates": [{"side": "bid", "event_time": "2026-09-24T12:00:04.100000Z", "price_level": "64000.00", "new_quantity": "0.06000000"}, {"side": "offer", "event_time": "2026-09-24T12:00:04.100000Z", "price_level": "64000.01", "new_quantity": "0.07000000"}]}]}
{"channel": "market_trades", "client_id": "", "timestamp": "2026-09-24T12:00:04.110000Z", "sequence_num": 14, "events": [{"type": "update", "trades": [{"trade_id": "1008", "product_id": "BTC-USD", "price": "64000.01", "size": "0.01500000", "side": "BUY", "time": "2026-09-24T12:00:04.110000Z"}]}]}
{"channel": "ticker", "client_id": "", "timestamp": "2026-09-24T12:00:04.120000Z", "sequence_num": 15, "events": [{"type": "update", "tickers": [{"type": "ticker", "product_id": "BTC-USD", "price": "64000.00", "best_bid": "64000.00", "best_bid_quantity": "0.06", "best_ask": "64000.01", "best_ask_quantity": "0.07"}]}]}
{"channel": "l2_data", "client_id": "", "timestamp": "2026-09-24T12:00:04.600000Z", "sequence_num": 16, "events": [{"type": "update", "product_id": "BTC-USD", "updates": [{"side": "bid", "event_time": "2026-09-24T12:00:04.600000Z", "price_level": "64000.00", "new_quantity": "0.06000000"}, {"side": "offer", "event_time": "2026-09-24T12:00:04.600000Z", "price_level": "64000.01", "new_quantity": "0.07000000"}]}]}
{"channel": "l2_data", "client_id": "", "timestamp": "2026-09-24T12:00:05.100000Z", "sequence_num": 17, "events": [{"type": "update", "product_id": "BTC-USD", "updates": [{"side": "bid", "event_time": "2026-09-24T12:00:05.100000Z", "price_level": "64000.00", "new_quantity": "0.06000000"}, {"side": "offer", "event_time": "2026-09-24T12:00:05.100000Z", "price_level": "64000.01", "new_quantity": "0.07000000"}]}]}
{"channel": "market_trades", "client_id": "", "timestamp": "2026-09-24T12:00:05.110000Z", "sequence_num": 18, "events": [{"type": "update", "trades": [{"trade_id": "1010", "product_id": "BTC-USD", "price": "64000.01", "size": "0.01500000", "side": "BUY", "time": "2026-09-24T12:00:05.110000Z"}]}]}
{"channel": "heartbeats", "client_id": "", "timestamp": "2026-09-24T12:00:05.130000Z", "sequence_num": 19, "events": [{"current_time": "2026-09-24T12:00:05.100000Z", "heartbeat_counter": 1}]}
{"channel": "l2_data", "client_id": "", "timestamp": "2026-09-24T12:00:05.600000Z", "sequence_num": 20, "events": [{"type": "update", "product_id": "BTC-USD", "updates": [{"side": "bid", "event_time": "2026-09-24T12:00:05.600000Z", "price_level": "64000.00", "new_quantity": "0.06000000"}, {"side": "offer", "event_time": "2026-09-24T12:00:05.600000Z", "price_level": "64000.01", "new_quantity": "0.07000000"}]}]}
{"channel": "l2_data", "client_id": "", "timestamp": "2026-09-24T12:00:06.100000Z", "sequence_num": 21, "events": [{"type": "update", "product_id": "BTC-USD", "updates": [{"side": "bid", "event_time": "2026-09-24T12:00:06.100000Z", "price_level": "64000.00", "new_quantity": "0.06000000"}, {"side": "offer", "event_time": "2026-09-24T12:00:06.100000Z", "price_level": "64000.01", "new_quantity": "0.07000000"}]}]}
{"channel": "market_trades", "client_id": "", "timestamp": "2026-09-24T12:00:06.110000Z", "sequence_num": 22, "events": [{"type": "update", "trades": [{"trade_id": "1012", "product_id": "BTC-USD", "price": "64000.01", "size": "0.01500000", "side": "BUY", "time": "2026-09-24T12:00:06.110000Z"}]}]}
{"channel": "ticker", "client_id": "", "timestamp": "2026-09-24T12:00:06.120000Z", "sequence_num": 23, "events": [{"type": "update", "tickers": [{"type": "ticker", "product_id": "BTC-USD", "price": "64000.00", "best_bid": "64000.00", "best_bid_quantity": "0.06", "best_ask": "64000.01", "best_ask_quantity": "0.07"}]}]}
{"channel": "l2_data", "client_id": "", "timestamp": "2026-09-24T12:00:06.600000Z", "sequence_num": 24, "events": [{"type": "update", "product_id": "BTC-USD", "updates": [{"side": "bid", "event_time": "2026-09-24T12:00:06.600000Z", "price_level": "64000.00", "new_quantity": "0.06000000"}, {"side": "offer", "event_time": "2026-09-24T12:00:06.600000Z", "price_level": "64000.01", "new_quantity": "0.07000000"}]}]}
{"channel": "l2_data", "client_id": "", "timestamp": "2026-09-24T12:00:07.100000Z", "sequence_num": 25, "events": [{"type": "update", "product_id": "BTC-USD", "updates": [{"side": "bid", "event_time": "2026-09-24T12:00:07.100000Z", "price_level": "64000.00", "new_quantity": "0.06000000"}, {"side": "offer", "event_time": "2026-09-24T12:00:07.100000Z", "price_level": "64000.01", "new_quantity": "0.07000000"}]}]}
{"channel": "market_trades", "client_id": "", "timestamp": "2026-09-24T12:00:07.110000Z", "sequence_num": 26, "events": [{"type": "update", "trades": [{"trade_id": "1014", "product_id": "BTC-USD", "price": "64000.01", "size": "0.01500000", "side": "BUY", "time": "2026-09-24T12:00:07.110000Z"}]}]}
{"channel": "l2_data", "client_id": "", "timestamp": "2026-09-24T12:00:07.600000Z", "sequence_num": 27, "events": [{"type": "update", "product_id": "BTC-USD", "updates": [{"side": "bid", "event_time": "2026-09-24T12:00:07.600000Z", "price_level": "64000.00", "new_quantity": "0.06000000"}, {"side": "offer", "event_time": "2026-09-24T12:00:07.600000Z", "price_level": "64000.01", "new_quantity": "0.07000000"}]}]}
{"channel": "l2_data", "client_id": "", "timestamp": "2026-09-24T12:00:08.100000Z", "sequence_num": 28, "events": [{"type": "update", "product_id": "BTC-USD", "updates": [{"side": "bid", "event_time": "2026-09-24T12:00:08.100000Z", "price_level": "64000.00", "new_quantity": "0.06000000"}, {"side": "offer", "event_time": "2026-09-24T12:00:08.100000Z", "price_level": "64000.01", "new_quantity": "0.07000000"}]}]}
{"channel": "market_trades", "client_id": "", "timestamp": "2026-09-24T12:00:08.110000Z", "sequence_num": 29, "events": [{"type": "update", "trades": [{"trade_id": "1016", "product_id": "BTC-USD", "price": "64000.01", "size": "0.01500000", "side": "BUY", "time": "2026-09-24T12:00:08.110000Z"}]}]}
{"channel": "ticker", "client_id": "", "timestamp": "2026-09-24T12:00:08.120000Z", "sequence_num": 30, "events": [{"type": "update", "tickers": [{"type": "ticker", "product_id": "BTC-USD", "price": "64000.00", "best_bid": "64000.00", "best_bid_quantity": "0.06", "best_ask": "64000.01", "best_ask_quantity": "0.07"}]}]}
{"channel": "l2_data", "client_id": "", "timestamp": "2026-09-24T12:00:08.600000Z", "sequence_num": 31, "events": [{"type": "update", "product_id": "BTC-USD", "updates": [{"side": "bid", "event_time": "2026-09-24T12:00:08.600000Z", "price_level": "64000.00", "new_quantity": "0.06000000"}, {"side": "offer", "event_time": "2026-09-24T12:00:08.600000Z", "price_level": "64000.01", "new_quantity": "0.07000000"}]}]}
{"channel": "l2_data", "client_id": "", "timestamp": "2026-09-24T12:00:09.100000Z", "sequence_num": 32, "events": [{"type": "update", "product_id": "BTC-USD", "updates": [{"side": "bid", "event_time": "2026-09-24T12:00:09.100000Z", "price_level": "64000.00", "new_quantity": "0.06000000"}, {"side": "offer", "event_time": "2026-09-24T12:00:09.100000Z", "price_level": "64000.01", "new_quantity": "0.07000000"}]}]}
{"channel": "market_trades", "client_id": "", "timestamp": "2026-09-24T12:00:09.110000Z", "sequence_num": 33, "events": [{"type": "update", "trades": [{"trade_id": "1018", "product_id": "BTC-USD", "price": "64000.01", "size": "0.01500000", "side": "BUY", "time": "2026-09-24T12:00:09.110000Z"}]}]}
{"channel": "l2_data", "client_id": "", "timestamp": "2026-09-24T12:00:09.600000Z", "sequence_num": 34, "events": [{"type": "update", "product_id": "BTC-USD", "updates": [{"side": "bid", "event_time": "2026-09-24T12:00:09.600000Z", "price_level": "64000.00", "new_quantity": "0.06000000"}, {"side": "offer", "event_time": "2026-09-24T12:00:09.600000Z", "price_level": "64000.01", "new_quantity": "0.07000000"}]}]}
{"channel": "l2_data", "client_id": "", "timestamp": "2026-09-24T12:00:10.100000Z", "sequence_num": 35, "events": [{"type": "update", "product_id": "BTC-USD", "updates": [{"side": "bid", "event_time": "2026-09-24T12:00:10.100000Z", "price_level": "64000.00", "new_quantity": "0"}, {"side": "bid", "event_time": "2026-09-24T12:00:10.100000Z", "price_level": "63999.85", "new_quantity": "0.06000000"}, {"side": "offer", "event_time": "2026-09-24T12:00:10.100000Z", "price_level": "63999.86", "new_quantity": "0.07000000"}]}]}
{"channel": "market_trades", "client_id": "", "timestamp": "2026-09-24T12:00:10.110000Z", "sequence_num": 36, "events": [{"type": "update", "trades": [{"trade_id": "1020", "product_id": "BTC-USD", "price": "63999.85", "size": "0.01500000", "side": "SELL", "time": "2026-09-24T12:00:10.110000Z"}]}]}
{"channel": "ticker", "client_id": "", "timestamp": "2026-09-24T12:00:10.120000Z", "sequence_num": 37, "events": [{"type": "update", "tickers": [{"type": "ticker", "product_id": "BTC-USD", "price": "63999.85", "best_bid": "63999.85", "best_bid_quantity": "0.06", "best_ask": "63999.86", "best_ask_quantity": "0.07"}]}]}
{"channel": "heartbeats", "client_id": "", "timestamp": "2026-09-24T12:00:10.130000Z", "sequence_num": 38, "events": [{"current_time": "2026-09-24T12:00:10.100000Z", "heartbeat_counter": 2}]}
{"channel": "l2_data", "client_id": "", "timestamp": "2026-09-24T12:00:10.600000Z", "sequence_num": 39, "events": [{"type": "update", "product_id": "BTC-USD", "updates": [{"side": "bid", "event_time": "2026-09-24T12:00:10.600000Z", "price_level": "63999.85", "new_quantity": "0"}, {"side": "bid", "event_time": "2026-09-24T12:00:10.600000Z", "price_level": "63999.70", "new_quantity": "0.06000000"}, {"side": "offer", "event_time": "2026-09-24T12:00:10.600000Z", "price_level": "63999.71", "new_quantity": "0.07000000"}]}]}
{"channel": "l2_data", "client_id": "", "timestamp": "2026-09-24T12:00:11.100000Z", "sequence_num": 40, "events": [{"type": "update", "product_id": "BTC-USD", "updates": [{"side": "bid", "event_time": "2026-09-24T12:00:11.100000Z", "price_level": "63999.70", "new_quantity": "0"}, {"side": "bid", "event_time": "2026-09-24T12:00:11.100000Z", "price_level": "63999.55", "new_quantity": "0.06000000"}, {"side": "offer", "event_time": "2026-09-24T12:00:11.100000Z", "price_level": "63999.56", "new_quantity": "0.07000000"}]}]}
{"channel": "market_trades", "client_id": "", "timestamp": "2026-09-24T12:00:11.110000Z", "sequence_num": 41, "events": [{"type": "update", "trades": [{"trade_id": "1022", "product_id": "BTC-USD", "price": "63999.55", "size": "0.01500000", "side": "SELL", "time": "2026-09-24T12:00:11.110000Z"}]}]}
{"channel": "l2_data", "client_id": "", "timestamp": "2026-09-24T12:00:11.600000Z", "sequence_num": 42, "events": [{"type": "update", "product_id": "BTC-USD", "updates": [{"side": "bid", "event_time": "2026-09-24T12:00:11.600000Z", "price_level": "63999.50", "new_quantity": "0"}, {"side": "bid", "event_time": "2026-09-24T12:00:11.600000Z", "price_level": "63999.55", "new_quantity": "0"}, {"side": "bid", "event_time": "2026-09-24T12:00:11.600000Z", "price_level": "63999.40", "new_quantity": "0.06000000"}, {"side": "offer", "event_time": "2026-09-24T12:00:11.600000Z", "price_level": "63999.41", "new_quantity": "0.07000000"}]}]}
{"channel": "l2_data", "client_id": "", "timestamp": "2026-09-24T12:00:12.100000Z", "sequence_num": 43, "events": [{"type": "update", "product_id": "BTC-USD", "updates": [{"side": "bid", "event_time": "2026-09-24T12:00:12.100000Z", "price_level": "63999.40", "new_quantity": "0"}, {"side": "bid", "event_time": "2026-09-24T12:00:12.100000Z", "price_level": "63999.25", "new_quantity": "0.06000000"}, {"side": "offer", "event_time": "2026-09-24T12:00:12.100000Z", "price_level": "63999.26", "new_quantity": "0.07000000"}]}]}
{"channel": "market_trades", "client_id": "", "timestamp": "2026-09-24T12:00:12.110000Z", "sequence_num": 44, "events": [{"type": "update", "trades": [{"trade_id": "1024", "product_id": "BTC-USD", "price": "63999.25", "size": "0.01500000", "side": "SELL", "time": "2026-09-24T12:00:12.110000Z"}]}]}
{"channel": "ticker", "client_id": "", "timestamp": "2026-09-24T12:00:12.120000Z", "sequence_num": 45, "events": [{"type": "update", "tickers": [{"type": "ticker", "product_id": "BTC-USD", "price": "63999.25", "best_bid": "63999.25", "best_bid_quantity": "0.06", "best_ask": "63999.26", "best_ask_quantity": "0.07"}]}]}
{"channel": "l2_data", "client_id": "", "timestamp": "2026-09-24T12:00:12.600000Z", "sequence_num": 46, "events": [{"type": "update", "product_id": "BTC-USD", "updates": [{"side": "bid", "event_time": "2026-09-24T12:00:12.600000Z", "price_level": "63999.25", "new_quantity": "0"}, {"side": "bid", "event_time": "2026-09-24T12:00:12.600000Z", "price_level": "63999.10", "new_quantity": "0.06000000"}, {"side": "offer", "event_time": "2026-09-24T12:00:12.600000Z", "price_level": "63999.11", "new_quantity": "0.07000000"}]}]}
{"channel": "l2_data", "client_id": "", "timestamp": "2026-09-24T12:00:13.100000Z", "sequence_num": 47, "events": [{"type": "update", "product_id": "BTC-USD", "updates": [{"side": "bid", "event_time": "2026-09-24T12:00:13.100000Z", "price_level": "63999.00", "new_quantity": "0"}, {"side": "bid", "event_time": "2026-09-24T12:00:13.100000Z", "price_level": "63999.10", "new_quantity": "0"}, {"side": "bid", "event_time": "2026-09-24T12:00:13.100000Z", "price_level": "63998.95", "new_quantity": "0.06000000"}, {"side": "offer", "event_time": "2026-09-24T12:00:13.100000Z", "price_level": "63998.96", "new_quantity": "0.07000000"}]}]}
{"channel": "market_trades", "client_id": "", "timestamp": "2026-09-24T12:00:13.110000Z", "sequence_num": 48, "events": [{"type": "update", "trades": [{"trade_id": "1026", "product_id": "BTC-USD", "price": "63998.95", "size": "0.01500000", "side": "SELL", "time": "2026-09-24T12:00:13.110000Z"}]}]}
{"channel": "l2_data", "client_id": "", "timestamp": "2026-09-24T12:00:13.600000Z", "sequence_num": 49, "events": [{"type": "update", "product_id": "BTC-USD", "updates": [{"side": "bid", "event_time": "2026-09-24T12:00:13.600000Z", "price_level": "63998.95", "new_quantity": "0"}, {"side": "bid", "event_time": "2026-09-24T12:00:13.600000Z", "price_level": "63998.80", "new_quantity": "0.06000000"}, {"side": "offer", "event_time": "2026-09-24T12:00:13.600000Z", "price_level": "63998.81", "new_quantity": "0.07000000"}]}]}
{"channel": "l2_data", "client_id": "", "timestamp": "2026-09-24T12:00:14.100000Z", "sequence_num": 50, "events": [{"type": "update", "product_id": "BTC-USD", "updates": [{"side": "bid", "event_time": "2026-09-24T12:00:14.100000Z", "price_level": "63998.80", "new_quantity": "0"}, {"side": "bid", "event_time": "2026-09-24T12:00:14.100000Z", "price_level": "63998.65", "new_quantity": "0.06000000"}, {"side": "offer", "event_time": "2026-09-24T12:00:14.100000Z", "price_level": "63998.66", "new_quantity": "0.07000000"}]}]}
{"channel": "market_trades", "client_id": "", "timestamp": "2026-09-24T12:00:14.110000Z", "sequence_num": 51, "events": [{"type": "update", "trades": [{"trade_id": "1028", "product_id": "BTC-USD", "price": "63998.65", "size": "0.01500000", "side": "SELL", "time": "2026-09-24T12:00:14.110000Z"}]}]}
{"channel": "ticker", "client_id": "", "timestamp": "2026-09-24T12:00:14.120000Z", "sequence_num": 52, "events": [{"type": "update", "tickers": [{"type": "ticker", "product_id": "BTC-USD", "price": "63998.65", "best_bid": "63998.65", "best_bid_quantity": "0.06", "best_ask": "63998.66", "best_ask_quantity": "0.07"}]}]}
{"channel": "l2_data", "client_id": "", "timestamp": "2026-09-24T12:00:14.600000Z", "sequence_num": 53, "events": [{"type": "update", "product_id": "BTC-USD", "updates": [{"side": "bid", "event_time": "2026-09-24T12:00:14.600000Z", "price_level": "63998.65", "new_quantity": "0"}, {"side": "bid", "event_time": "2026-09-24T12:00:14.600000Z", "price_level": "63998.50", "new_quantity": "0.06000000"}, {"side": "offer", "event_time": "2026-09-24T12:00:14.600000Z", "price_level": "63998.51", "new_quantity": "0.07000000"}]}]}
{"channel": "l2_data", "client_id": "", "timestamp": "2026-09-24T12:00:15.100000Z", "sequence_num": 54, "events": [{"type": "update", "product_id": "BTC-USD", "updates": [{"side": "bid", "event_time": "2026-09-24T12:00:15.100000Z", "price_level": "63998.50", "new_quantity": "0"}, {"side": "bid", "event_time": "2026-09-24T12:00:15.100000Z", "price_level": "63998.35", "new_quantity": "0.06000000"}, {"side": "offer", "event_time": "2026-09-24T12:00:15.100000Z", "price_level": "63998.36", "new_quantity": "0.07000000"}]}]}
{"channel": "market_trades", "client_id": "", "timestamp": "2026-09-24T12:00:15.110000Z", "sequence_num": 55, "events": [{"type": "update", "trades": [{"trade_id": "1030", "product_id": "BTC-USD", "price": "63998.35", "size": "0.01500000", "side": "SELL", "time": "2026-09-24T12:00:15.110000Z"}]}]}
{"channel": "heartbeats", "client_id": "", "timestamp": "2026-09-24T12:00:15.130000Z", "sequence_num": 56, "events": [{"current_time": "2026-09-24T12:00:15.100000Z", "heartbeat_counter": 3}]}
{"channel": "l2_data", "client_id": "", "timestamp": "2026-09-24T12:00:15.600000Z", "sequence_num": 57, "events": [{"type": "update", "product_id": "BTC-USD", "updates": [{"side": "bid", "event_time": "2026-09-24T12:00:15.600000Z", "price_level": "63998.35", "new_quantity": "0"}, {"side": "bid", "event_time": "2026-09-24T12:00:15.600000Z", "price_level": "63998.20", "new_quantity": "0.06000000"}, {"side": "offer", "event_time": "2026-09-24T12:00:15.600000Z", "price_level": "63998.21", "new_quantity": "0.07000000"}]}]}
{"channel": "l2_data", "client_id": "", "timestamp": "2026-09-24T12:00:16.100000Z", "sequence_num": 58, "events": [{"type": "update", "product_id": "BTC-USD", "updates": [{"side": "bid", "event_time": "2026-09-24T12:00:16.100000Z", "price_level": "63998.20", "new_quantity": "0"}, {"side": "bid", "event_time": "2026-09-24T12:00:16.100000Z", "price_level": "63998.05", "new_quantity": "0.06000000"}, {"side": "offer", "event_time": "2026-09-24T12:00:16.100000Z", "price_level": "63998.06", "new_quantity": "0.07000000"}]}]}
{"channel": "market_trades", "client_id": "", "timestamp": "2026-09-24T12:00:16.110000Z", "sequence_num": 59, "events": [{"type": "update", "trades": [{"trade_id": "1032", "product_id": "BTC-USD", "price": "63998.05", "size": "0.01500000", "side": "SELL", "time": "2026-09-24T12:00:16.110000Z"}]}]}
{"channel": "ticker", "client_id": "", "timestamp": "2026-09-24T12:00:16.120000Z", "sequence_num": 60, "events": [{"type": "update", "tickers": [{"type": "ticker", "product_id": "BTC-USD", "price": "63998.05", "best_bid": "63998.05", "best_bid_quantity": "0.06", "best_ask": "63998.06", "best_ask_quantity": "0.07"}]}]}
{"channel": "l2_data", "client_id": "", "timestamp": "2026-09-24T12:00:16.600000Z", "sequence_num": 61, "events": [{"type": "update", "product_id": "BTC-USD", "updates": [{"side": "bid", "event_time": "2026-09-24T12:00:16.600000Z", "price_level": "63998.00", "new_quantity": "0"}, {"side": "bid", "event_time": "2026-09-24T12:00:16.600000Z", "price_level": "63998.05", "new_quantity": "0"}, {"side": "bid", "event_time": "2026-09-24T12:00:16.600000Z", "price_level": "63997.90", "new_quantity": "0.06000000"}, {"side": "offer", "event_time": "2026-09-24T12:00:16.600000Z", "price_level": "63997.91", "new_quantity": "0.07000000"}]}]}
{"channel": "l2_data", "client_id": "", "timestamp": "2026-09-24T12:00:17.100000Z", "sequence_num": 62, "events": [{"type": "update", "product_id": "BTC-USD", "updates": [{"side": "bid", "event_time": "2026-09-24T12:00:17.100000Z", "price_level": "63997.90", "new_quantity": "0"}, {"side": "bid", "event_time": "2026-09-24T12:00:17.100000Z", "price_level": "63997.75", "new_quantity": "0.06000000"}, {"side": "offer", "event_time": "2026-09-24T12:00:17.100000Z", "price_level": "63997.76", "new_quantity": "0.07000000"}]}]}
{"channel": "market_trades", "client_id": "", "timestamp": "2026-09-24T12:00:17.110000Z", "sequence_num": 63, "events": [{"type": "update", "trades": [{"trade_id": "1034", "product_id": "BTC-USD", "price": "63997.75", "size": "0.01500000", "side": "SELL", "time": "2026-09-24T12:00:17.110000Z"}]}]}
{"channel": "l2_data", "client_id": "", "timestamp": "2026-09-24T12:00:17.600000Z", "sequence_num": 64, "events": [{"type": "update", "product_id": "BTC-USD", "updates": [{"side": "bid", "event_time": "2026-09-24T12:00:17.600000Z", "price_level": "63997.75", "new_quantity": "0"}, {"side": "bid", "event_time": "2026-09-24T12:00:17.600000Z", "price_level": "63997.60", "new_quantity": "0.06000000"}, {"side": "offer", "event_time": "2026-09-24T12:00:17.600000Z", "price_level": "63997.61", "new_quantity": "0.07000000"}]}]}
{"channel": "l2_data", "client_id": "", "timestamp": "2026-09-24T12:00:18.100000Z", "sequence_num": 65, "events": [{"type": "update", "product_id": "BTC-USD", "updates": [{"side": "bid", "event_time": "2026-09-24T12:00:18.100000Z", "price_level": "63997.50", "new_quantity": "0"}, {"side": "bid", "event_time": "2026-09-24T12:00:18.100000Z", "price_level": "63997.60", "new_quantity": "0"}, {"side": "bid", "event_time": "2026-09-24T12:00:18.100000Z", "price_level": "63997.45", "new_quantity": "0.06000000"}, {"side": "offer", "event_time": "2026-09-24T12:00:18.100000Z", "price_level": "63997.46", "new_quantity": "0.07000000"}]}]}
{"channel": "market_trades", "client_id": "", "timestamp": "2026-09-24T12:00:18.110000Z", "sequence_num": 66, "events": [{"type": "update", "trades": [{"trade_id": "1036", "product_id": "BTC-USD", "price": "63997.45", "size": "0.01500000", "side": "SELL", "time": "2026-09-24T12:00:18.110000Z"}]}]}
{"channel": "ticker", "client_id": "", "timestamp": "2026-09-24T12:00:18.120000Z", "sequence_num": 67, "events": [{"type": "update", "tickers": [{"type": "ticker", "product_id": "BTC-USD", "price": "63997.45", "best_bid": "63997.45", "best_bid_quantity": "0.06", "best_ask": "63997.46", "best_ask_quantity": "0.07"}]}]}
{"channel": "l2_data", "client_id": "", "timestamp": "2026-09-24T12:00:18.600000Z", "sequence_num": 68, "events": [{"type": "update", "product_id": "BTC-USD", "updates": [{"side": "bid", "event_time": "2026-09-24T12:00:18.600000Z", "price_level": "63997.45", "new_quantity": "0"}, {"side": "bid", "event_time": "2026-09-24T12:00:18.600000Z", "price_level": "63997.30", "new_quantity": "0.06000000"}, {"side": "offer", "event_time": "2026-09-24T12:00:18.600000Z", "price_level": "63997.31", "new_quantity": "0.07000000"}]}]}
{"channel": "l2_data", "client_id": "", "timestamp": "2026-09-24T12:00:19.100000Z", "sequence_num": 69, "events": [{"type": "update", "product_id": "BTC-USD", "updates": [{"side": "bid", "event_time": "2026-09-24T12:00:19.100000Z", "price_level": "63997.30", "new_quantity": "0"}, {"side": "bid", "event_time": "2026-09-24T12:00:19.100000Z", "price_level": "63997.15", "new_quantity": "0.06000000"}, {"side": "offer", "event_time": "2026-09-24T12:00:19.100000Z", "price_level": "63997.16", "new_quantity": "0.07000000"}]}]}
{"channel": "market_trades", "client_id": "", "timestamp": "2026-09-24T12:00:19.110000Z", "sequence_num": 70, "events": [{"type": "update", "trades": [{"trade_id": "1038", "product_id": "BTC-USD", "price": "63997.15", "size": "0.01500000", "side": "SELL", "time": "2026-09-24T12:00:19.110000Z"}]}]}
{"channel": "l2_data", "client_id": "", "timestamp": "2026-09-24T12:00:19.600000Z", "sequence_num": 71, "events": [{"type": "update", "product_id": "BTC-USD", "updates": [{"side": "bid", "event_time": "2026-09-24T12:00:19.600000Z", "price_level": "63997.15", "new_quantity": "0"}, {"side": "bid", "event_time": "2026-09-24T12:00:19.600000Z", "price_level": "63997.00", "new_quantity": "0.06000000"}, {"side": "offer", "event_time": "2026-09-24T12:00:19.600000Z", "price_level": "63997.01", "new_quantity": "0.07000000"}]}]}
{"channel": "l2_data", "client_id": "", "timestamp": "2026-09-24T12:00:20.100000Z", "sequence_num": 72, "events": [{"type": "update", "product_id": "BTC-USD", "updates": [{"side": "bid", "event_time": "2026-09-24T12:00:20.100000Z", "price_level": "63997.00", "new_quantity": "0.06000000"}, {"side": "offer", "event_time": "2026-09-24T12:00:20.100000Z", "price_level": "63997.01", "new_quantity": "0.07000000"}]}]}
{"channel": "market_trades", "client_id": "", "timestamp": "2026-09-24T12:00:20.110000Z", "sequence_num": 73, "events": [{"type": "update", "trades": [{"trade_id": "1040", "product_id": "BTC-USD", "price": "63997.01", "size": "0.01500000", "side": "BUY", "time": "2026-09-24T12:00:20.110000Z"}]}]}
{"channel": "ticker", "client_id": "", "timestamp": "2026-09-24T12:00:20.120000Z", "sequence_num": 74, "events": [{"type": "update", "tickers": [{"type": "ticker", "product_id": "BTC-USD", "price": "63997.00", "best_bid": "63997.00", "best_bid_quantity": "0.06", "best_ask": "63997.01", "best_ask_quantity": "0.07"}]}]}
{"channel": "heartbeats", "client_id": "", "timestamp": "2026-09-24T12:00:20.130000Z", "sequence_num": 75, "events": [{"current_time": "2026-09-24T12:00:20.100000Z", "heartbeat_counter": 4}]}
{"channel": "l2_data", "client_id": "", "timestamp": "2026-09-24T12:00:20.600000Z", "sequence_num": 76, "events": [{"type": "update", "product_id": "BTC-USD", "updates": [{"side": "bid", "event_time": "2026-09-24T12:00:20.600000Z", "price_level": "63997.00", "new_quantity": "0.06000000"}, {"side": "offer", "event_time": "2026-09-24T12:00:20.600000Z", "price_level": "63997.01", "new_quantity": "0.07000000"}]}]}
{"channel": "l2_data", "client_id": "", "timestamp": "2026-09-24T12:00:21.100000Z", "sequence_num": 77, "events": [{"type": "update", "product_id": "BTC-USD", "updates": [{"side": "bid", "event_time": "2026-09-24T12:00:21.100000Z", "price_level": "63997.00", "new_quantity": "0.06000000"}, {"side": "offer", "event_time": "2026-09-24T12:00:21.100000Z", "price_level": "63997.01", "new_quantity": "0.07000000"}]}]}
{"channel": "market_trades", "client_id": "", "timestamp": "2026-09-24T12:00:21.110000Z", "sequence_num": 78, "events": [{"type": "update", "trades": [{"trade_id": "1042", "product_id": "BTC-USD", "price": "63997.01", "size": "0.01500000", "side": "BUY", "time": "2026-09-24T12:00:21.110000Z"}]}]}
{"channel": "l2_data", "client_id": "", "timestamp": "2026-09-24T12:00:21.600000Z", "sequence_num": 79, "events": [{"type": "update", "product_id": "BTC-USD", "updates": [{"side": "bid", "event_time": "2026-09-24T12:00:21.600000Z", "price_level": "63997.00", "new_quantity": "0.06000000"}, {"side": "offer", "event_time": "2026-09-24T12:00:21.600000Z", "price_level": "63997.01", "new_quantity": "0.07000000"}]}]}
{"channel": "l2_data", "client_id": "", "timestamp": "2026-09-24T12:00:22.100000Z", "sequence_num": 80, "events": [{"type": "update", "product_id": "BTC-USD", "updates": [{"side": "bid", "event_time": "2026-09-24T12:00:22.100000Z", "price_level": "63997.00", "new_quantity": "0.06000000"}, {"side": "offer", "event_time": "2026-09-24T12:00:22.100000Z", "price_level": "63997.01", "new_quantity": "0.07000000"}]}]}
{"channel": "market_trades", "client_id": "", "timestamp": "2026-09-24T12:00:22.110000Z", "sequence_num": 81, "events": [{"type": "update", "trades": [{"trade_id": "1044", "product_id": "BTC-USD", "price": "63997.01", "size": "0.01500000", "side": "BUY", "time": "2026-09-24T12:00:22.110000Z"}]}]}
{"channel": "ticker", "client_id": "", "timestamp": "2026-09-24T12:00:22.120000Z", "sequence_num": 82, "events": [{"type": "update", "tickers": [{"type": "ticker", "product_id": "BTC-USD", "price": "63997.00", "best_bid": "63997.00", "best_bid_quantity": "0.06", "best_ask": "63997.01", "best_ask_quantity": "0.07"}]}]}
{"channel": "l2_data", "client_id": "", "timestamp": "2026-09-24T12:00:22.600000Z", "sequence_num": 83, "events": [{"type": "update", "product_id": "BTC-USD", "updates": [{"side": "bid", "event_time": "2026-09-24T12:00:22.600000Z", "price_level": "63997.00", "new_quantity": "0.06000000"}, {"side": "offer", "event_time": "2026-09-24T12:00:22.600000Z", "price_level": "63997.01", "new_quantity": "0.07000000"}]}]}
{"channel": "l2_data", "client_id": "", "timestamp": "2026-09-24T12:00:23.100000Z", "sequence_num": 84, "events": [{"type": "update", "product_id": "BTC-USD", "updates": [{"side": "bid", "event_time": "2026-09-24T12:00:23.100000Z", "price_level": "63997.00", "new_quantity": "0.06000000"}, {"side": "offer", "event_time": "2026-09-24T12:00:23.100000Z", "price_level": "63997.01", "new_quantity": "0.07000000"}]}]}
{"channel": "market_trades", "client_id": "", "timestamp": "2026-09-24T12:00:23.110000Z", "sequence_num": 85, "events": [{"type": "update", "trades": [{"trade_id": "1046", "product_id": "BTC-USD", "price": "63997.01", "size": "0.01500000", "side": "BUY", "time": "2026-09-24T12:00:23.110000Z"}]}]}
{"channel": "l2_data", "client_id": "", "timestamp": "2026-09-24T12:00:23.600000Z", "sequence_num": 86, "events": [{"type": "update", "product_id": "BTC-USD", "updates": [{"side": "bid", "event_time": "2026-09-24T12:00:23.600000Z", "price_level": "63997.00", "new_quantity": "0.06000000"}, {"side": "offer", "event_time": "2026-09-24T12:00:23.600000Z", "price_level": "63997.01", "new_quantity": "0.07000000"}]}]}
{"channel": "l2_data", "client_id": "", "timestamp": "2026-09-24T12:00:24.100000Z", "sequence_num": 87, "events": [{"type": "update", "product_id": "BTC-USD", "updates": [{"side": "bid", "event_time": "2026-09-24T12:00:24.100000Z", "price_level": "63997.00", "new_quantity": "0.06000000"}, {"side": "offer", "event_time": "2026-09-24T12:00:24.100000Z", "price_level": "63997.01", "new_quantity": "0.07000000"}]}]}
{"channel": "market_trades", "client_id": "", "timestamp": "2026-09-24T12:00:24.110000Z", "sequence_num": 88, "events": [{"type": "update", "trades": [{"trade_id": "1048", "product_id": "BTC-USD", "price": "63997.01", "size": "0.01500000", "side": "BUY", "time": "2026-09-24T12:00:24.110000Z"}]}]}
{"channel": "ticker", "client_id": "", "timestamp": "2026-09-24T12:00:24.120000Z", "sequence_num": 89, "events": [{"type": "update", "tickers": [{"type": "ticker", "product_id": "BTC-USD", "price": "63997.00", "best_bid": "63997.00", "best_bid_quantity": "0.06", "best_ask": "63997.01", "best_ask_quantity": "0.07"}]}]}
{"channel": "l2_data", "client_id": "", "timestamp": "2026-09-24T12:00:24.600000Z", "sequence_num": 90, "events": [{"type": "update", "product_id": "BTC-USD", "updates": [{"side": "bid", "event_time": "2026-09-24T12:00:24.600000Z", "price_level": "63997.00", "new_quantity": "0.06000000"}, {"side": "offer", "event_time": "2026-09-24T12:00:24.600000Z", "price_level": "63997.01", "new_quantity": "0.07000000"}]}]}
{"channel": "l2_data", "client_id": "", "timestamp": "2026-09-24T12:00:25.100000Z", "sequence_num": 91, "events": [{"type": "update", "product_id": "BTC-USD", "updates": [{"side": "bid", "event_time": "2026-09-24T12:00:25.100000Z", "price_level": "63997.00", "new_quantity": "0.06000000"}, {"side": "offer", "event_time": "2026-09-24T12:00:25.100000Z", "price_level": "63997.01", "new_quantity": "0.07000000"}]}]}
{"channel": "market_trades", "client_id": "", "timestamp": "2026-09-24T12:00:25.110000Z", "sequence_num": 92, "events": [{"type": "update", "trades": [{"trade_id": "1050", "product_id": "BTC-USD", "price": "63997.01", "size": "0.01500000", "side": "BUY", "time": "2026-09-24T12:00:25.110000Z"}]}]}
{"channel": "heartbeats", "client_id": "", "timestamp": "2026-09-24T12:00:25.130000Z", "sequence_num": 93, "events": [{"current_time": "2026-09-24T12:00:25.100000Z", "heartbeat_counter": 5}]}
{"channel": "l2_data", "client_id": "", "timestamp": "2026-09-24T12:00:25.600000Z", "sequence_num": 94, "events": [{"type": "update", "product_id": "BTC-USD", "updates": [{"side": "bid", "event_time": "2026-09-24T12:00:25.600000Z", "price_level": "63997.00", "new_quantity": "0.06000000"}, {"side": "offer", "event_time": "2026-09-24T12:00:25.600000Z", "price_level": "63997.01", "new_quantity": "0.07000000"}]}]}
{"channel": "l2_data", "client_id": "", "timestamp": "2026-09-24T12:00:26.100000Z", "sequence_num": 95, "events": [{"type": "update", "product_id": "BTC-USD", "updates": [{"side": "bid", "event_time": "2026-09-24T12:00:26.100000Z", "price_level": "63997.00", "new_quantity": "0.06000000"}, {"side": "offer", "event_time": "2026-09-24T12:00:26.100000Z", "price_level": "63997.01", "new_quantity": "0.07000000"}]}]}
{"channel": "market_trades", "client_id": "", "timestamp": "2026-09-24T12:00:26.110000Z", "sequence_num": 96, "events": [{"type": "update", "trades": [{"trade_id": "1052", "product_id": "BTC-USD", "price": "63997.01", "size": "0.01500000", "side": "BUY", "time": "2026-09-24T12:00:26.110000Z"}]}]}
{"channel": "ticker", "client_id": "", "timestamp": "2026-09-24T12:00:26.120000Z", "sequence_num": 97, "events": [{"type": "update", "tickers": [{"type": "ticker", "product_id": "BTC-USD", "price": "63997.00", "best_bid": "63997.00", "best_bid_quantity": "0.06", "best_ask": "63997.01", "best_ask_quantity": "0.07"}]}]}
{"channel": "l2_data", "client_id": "", "timestamp": "2026-09-24T12:00:26.600000Z", "sequence_num": 98, "events": [{"type": "update", "product_id": "BTC-USD", "updates": [{"side": "bid", "event_time": "2026-09-24T12:00:26.600000Z", "price_level": "63997.00", "new_quantity": "0.06000000"}, {"side": "offer", "event_time": "2026-09-24T12:00:26.600000Z", "price_level": "63997.01", "new_quantity": "0.07000000"}]}]}
{"channel": "l2_data", "client_id": "", "timestamp": "2026-09-24T12:00:27.100000Z", "sequence_num": 99, "events": [{"type": "update", "product_id": "BTC-USD", "updates": [{"side": "bid", "event_time": "2026-09-24T12:00:27.100000Z", "price_level": "63997.00", "new_quantity": "0.06000000"}, {"side": "offer", "event_time": "2026-09-24T12:00:27.100000Z", "price_level": "63997.01", "new_quantity": "0.07000000"}]}]}
{"channel": "market_trades", "client_id": "", "timestamp": "2026-09-24T12:00:27.110000Z", "sequence_num": 100, "events": [{"type": "update", "trades": [{"trade_id": "1054", "product_id": "BTC-USD", "price": "63997.01", "size": "0.01500000", "side": "BUY", "time": "2026-09-24T12:00:27.110000Z"}]}]}
{"channel": "l2_data", "client_id": "", "timestamp": "2026-09-24T12:00:27.600000Z", "sequence_num": 101, "events": [{"type": "update", "product_id": "BTC-USD", "updates": [{"side": "bid", "event_time": "2026-09-24T12:00:27.600000Z", "price_level": "63997.00", "new_quantity": "0.06000000"}, {"side": "offer", "event_time": "2026-09-24T12:00:27.600000Z", "price_level": "63997.01", "new_quantity": "0.07000000"}]}]}
{"channel": "l2_data", "client_id": "", "timestamp": "2026-09-24T12:00:28.100000Z", "sequence_num": 102, "events": [{"type": "update", "product_id": "BTC-USD", "updates": [{"side": "bid", "event_time": "2026-09-24T12:00:28.100000Z", "price_level": "63997.00", "new_quantity": "0.06000000"}, {"side": "offer", "event_time": "2026-09-24T12:00:28.100000Z", "price_level": "63997.01", "new_quantity": "0.07000000"}]}]}
{"channel": "market_trades", "client_id": "", "timestamp": "2026-09-24T12:00:28.110000Z", "sequence_num": 103, "events": [{"type": "update", "trades": [{"trade_id": "1056", "product_id": "BTC-USD", "price": "63997.01", "size": "0.01500000", "side": "BUY", "time": "2026-09-24T12:00:28.110000Z"}]}]}
{"channel": "ticker", "client_id": "", "timestamp": "2026-09-24T12:00:28.120000Z", "sequence_num": 104, "events": [{"type": "update", "tickers": [{"type": "ticker", "product_id": "BTC-USD", "price": "63997.00", "best_bid": "63997.00", "best_bid_quantity": "0.06", "best_ask": "63997.01", "best_ask_quantity": "0.07"}]}]}
{"channel": "l2_data", "client_id": "", "timestamp": "2026-09-24T12:00:28.600000Z", "sequence_num": 105, "events": [{"type": "update", "product_id": "BTC-USD", "updates": [{"side": "bid", "event_time": "2026-09-24T12:00:28.600000Z", "price_level": "63997.00", "new_quantity": "0.06000000"}, {"side": "offer", "event_time": "2026-09-24T12:00:28.600000Z", "price_level": "63997.01", "new_quantity": "0.07000000"}]}]}
{"channel": "l2_data", "client_id": "", "timestamp": "2026-09-24T12:00:29.100000Z", "sequence_num": 106, "events": [{"type": "update", "product_id": "BTC-USD", "updates": [{"side": "bid", "event_time": "2026-09-24T12:00:29.100000Z", "price_level": "63997.00", "new_quantity": "0.06000000"}, {"side": "offer", "event_time": "2026-09-24T12:00:29.100000Z", "price_level": "63997.01", "new_quantity": "0.07000000"}]}]}
{"channel": "market_trades", "client_id": "", "timestamp": "2026-09-24T12:00:29.110000Z", "sequence_num": 107, "events": [{"type": "update", "trades": [{"trade_id": "1058", "product_id": "BTC-USD", "price": "63997.01", "size": "0.01500000", "side": "BUY", "time": "2026-09-24T12:00:29.110000Z"}]}]}
{"channel": "l2_data", "client_id": "", "timestamp": "2026-09-24T12:00:29.600000Z", "sequence_num": 108, "events": [{"type": "update", "product_id": "BTC-USD", "updates": [{"side": "bid", "event_time": "2026-09-24T12:00:29.600000Z", "price_level": "63997.00", "new_quantity": "0.06000000"}, {"side": "offer", "event_time": "2026-09-24T12:00:29.600000Z", "price_level": "63997.01", "new_quantity": "0.07000000"}]}]}
{"channel": "l2_data", "client_id": "", "timestamp": "2026-09-24T12:00:30.100000Z", "sequence_num": 109, "events": [{"type": "update", "product_id": "BTC-USD", "updates": [{"side": "offer", "event_time": "2026-09-24T12:00:30.100000Z", "price_level": "63997.01", "new_quantity": "0"}, {"side": "bid", "event_time": "2026-09-24T12:00:30.100000Z", "price_level": "63997.10", "new_quantity": "0.06000000"}, {"side": "offer", "event_time": "2026-09-24T12:00:30.100000Z", "price_level": "63997.11", "new_quantity": "0.07000000"}]}]}
{"channel": "market_trades", "client_id": "", "timestamp": "2026-09-24T12:00:30.110000Z", "sequence_num": 110, "events": [{"type": "update", "trades": [{"trade_id": "1060", "product_id": "BTC-USD", "price": "63997.11", "size": "0.01500000", "side": "BUY", "time": "2026-09-24T12:00:30.110000Z"}]}]}
{"channel": "ticker", "client_id": "", "timestamp": "2026-09-24T12:00:30.120000Z", "sequence_num": 111, "events": [{"type": "update", "tickers": [{"type": "ticker", "product_id": "BTC-USD", "price": "63997.10", "best_bid": "63997.10", "best_bid_quantity": "0.06", "best_ask": "63997.11", "best_ask_quantity": "0.07"}]}]}
{"channel": "heartbeats", "client_id": "", "timestamp": "2026-09-24T12:00:30.130000Z", "sequence_num": 112, "events": [{"current_time": "2026-09-24T12:00:30.100000Z", "heartbeat_counter": 6}]}
{"channel": "l2_data", "client_id": "", "timestamp": "2026-09-24T12:00:30.600000Z", "sequence_num": 113, "events": [{"type": "update", "product_id": "BTC-USD", "updates": [{"side": "offer", "event_time": "2026-09-24T12:00:30.600000Z", "price_level": "63997.11", "new_quantity": "0"}, {"side": "offer", "event_time": "2026-09-24T12:00:30.600000Z", "price_level": "63997.16", "new_quantity": "0"}, {"side": "bid", "event_time": "2026-09-24T12:00:30.600000Z", "price_level": "63997.20", "new_quantity": "0.06000000"}, {"side": "offer", "event_time": "2026-09-24T12:00:30.600000Z", "price_level": "63997.21", "new_quantity": "0.07000000"}]}]}
{"channel": "l2_data", "client_id": "", "timestamp": "2026-09-24T12:00:31.100000Z", "sequence_num": 114, "events": [{"type": "update", "product_id": "BTC-USD", "updates": [{"side": "offer", "event_time": "2026-09-24T12:00:31.100000Z", "price_level": "63997.21", "new_quantity": "0"}, {"side": "bid", "event_time": "2026-09-24T12:00:31.100000Z", "price_level": "63997.30", "new_quantity": "0.06000000"}, {"side": "offer", "event_time": "2026-09-24T12:00:31.100000Z", "price_level": "63997.31", "new_quantity": "0.07000000"}]}]}
{"channel": "market_trades", "client_id": "", "timestamp": "2026-09-24T12:00:31.110000Z", "sequence_num": 115, "events": [{"type": "update", "trades": [{"trade_id": "1062", "product_id": "BTC-USD", "price": "63997.31", "size": "0.01500000", "side": "BUY", "time": "2026-09-24T12:00:31.110000Z"}]}]}
{"channel": "l2_data", "client_id": "", "timestamp": "2026-09-24T12:00:31.600000Z", "sequence_num": 116, "events": [{"type": "update", "product_id": "BTC-USD", "updates": [{"side": "offer", "event_time": "2026-09-24T12:00:31.600000Z", "price_level": "63997.31", "new_quantity": "0"}, {"side": "bid", "event_time": "2026-09-24T12:00:31.600000Z", "price_level": "63997.40", "new_quantity": "0.06000000"}, {"side": "offer", "event_time": "2026-09-24T12:00:31.600000Z", "price_level": "63997.41", "new_quantity": "0.07000000"}]}]}
{"channel": "l2_data", "client_id": "", "timestamp": "2026-09-24T12:00:32.100000Z", "sequence_num": 117, "events": [{"type": "update", "product_id": "BTC-USD", "updates": [{"side": "offer", "event_time": "2026-09-24T12:00:32.100000Z", "price_level": "63997.41", "new_quantity": "0"}, {"side": "offer", "event_time": "2026-09-24T12:00:32.100000Z", "price_level": "63997.46", "new_quantity": "0"}, {"side": "bid", "event_time": "2026-09-24T12:00:32.100000Z", "price_level": "63997.50", "new_quantity": "0.06000000"}, {"side": "offer", "event_time": "2026-09-24T12:00:32.100000Z", "price_level": "63997.51", "new_quantity": "0.07000000"}]}]}
{"channel": "market_trades", "client_id": "", "timestamp": "2026-09-24T12:00:32.110000Z", "sequence_num": 118, "events": [{"type": "update", "trades": [{"trade_id": "1064", "product_id": "BTC-USD", "price": "63997.51", "size": "0.01500000", "side": "BUY", "time": "2026-09-24T12:00:32.110000Z"}]}]}
{"channel": "ticker", "client_id": "", "timestamp": "2026-09-24T12:00:32.120000Z", "sequence_num": 119, "events": [{"type": "update", "tickers": [{"type": "ticker", "product_id": "BTC-USD", "price": "63997.50", "best_bid": "63997.50", "best_bid_quantity": "0.06", "best_ask": "63997.51", "best_ask_quantity": "0.07"}]}]}
{"channel": "l2_data", "client_id": "", "timestamp": "2026-09-24T12:00:32.600000Z", "sequence_num": 120, "events": [{"type": "update", "product_id": "BTC-USD", "updates": [{"side": "offer", "event_time": "2026-09-24T12:00:32.600000Z", "price_level": "63997.51", "new_quantity": "0"}, {"side": "bid", "event_time": "2026-09-24T12:00:32.600000Z", "price_level": "63997.60", "new_quantity": "0.06000000"}, {"side": "offer", "event_time": "2026-09-24T12:00:32.600000Z", "price_level": "63997.61", "new_quantity": "0.07000000"}]}]}
{"channel": "l2_data", "client_id": "", "timestamp": "2026-09-24T12:00:33.100000Z", "sequence_num": 121, "events": [{"type": "update", "product_id": "BTC-USD", "updates": [{"side": "offer", "event_time": "2026-09-24T12:00:33.100000Z", "price_level": "63997.61", "new_quantity": "0"}, {"side": "bid", "event_time": "2026-09-24T12:00:33.100000Z", "price_level": "63997.70", "new_quantity": "0.06000000"}, {"side": "offer", "event_time": "2026-09-24T12:00:33.100000Z", "price_level": "63997.71", "new_quantity": "0.07000000"}]}]}
{"channel": "market_trades", "client_id": "", "timestamp": "2026-09-24T12:00:33.110000Z", "sequence_num": 122, "events": [{"type": "update", "trades": [{"trade_id": "1066", "product_id": "BTC-USD", "price": "63997.71", "size": "0.01500000", "side": "BUY", "time": "2026-09-24T12:00:33.110000Z"}]}]}
{"channel": "l2_data", "client_id": "", "timestamp": "2026-09-24T12:00:33.600000Z", "sequence_num": 123, "events": [{"type": "update", "product_id": "BTC-USD", "updates": [{"side": "offer", "event_time": "2026-09-24T12:00:33.600000Z", "price_level": "63997.71", "new_quantity": "0"}, {"side": "offer", "event_time": "2026-09-24T12:00:33.600000Z", "price_level": "63997.76", "new_quantity": "0"}, {"side": "bid", "event_time": "2026-09-24T12:00:33.600000Z", "price_level": "63997.80", "new_quantity": "0.06000000"}, {"side": "offer", "event_time": "2026-09-24T12:00:33.600000Z", "price_level": "63997.81", "new_quantity": "0.07000000"}]}]}
{"channel": "l2_data", "client_id": "", "timestamp": "2026-09-24T12:00:34.100000Z", "sequence_num": 124, "events": [{"type": "update", "product_id": "BTC-USD", "updates": [{"side": "offer", "event_time": "2026-09-24T12:00:34.100000Z", "price_level": "63997.81", "new_quantity": "0"}, {"side": "bid", "event_time": "2026-09-24T12:00:34.100000Z", "price_level": "63997.90", "new_quantity": "0.06000000"}, {"side": "offer", "event_time": "2026-09-24T12:00:34.100000Z", "price_level": "63997.91", "new_quantity": "0.07000000"}]}]}
{"channel": "market_trades", "client_id": "", "timestamp": "2026-09-24T12:00:34.110000Z", "sequence_num": 125, "events": [{"type": "update", "trades": [{"trade_id": "1068", "product_id": "BTC-USD", "price": "63997.91", "size": "0.01500000", "side": "BUY", "time": "2026-09-24T12:00:34.110000Z"}]}]}
{"channel": "ticker", "client_id": "", "timestamp": "2026-09-24T12:00:34.120000Z", "sequence_num": 126, "events": [{"type": "update", "tickers": [{"type": "ticker", "product_id": "BTC-USD", "price": "63997.90", "best_bid": "63997.90", "best_bid_quantity": "0.06", "best_ask": "63997.91", "best_ask_quantity": "0.07"}]}]}
{"channel": "l2_data", "client_id": "", "timestamp": "2026-09-24T12:00:34.600000Z", "sequence_num": 127, "events": [{"type": "update", "product_id": "BTC-USD", "updates": [{"side": "offer", "event_time": "2026-09-24T12:00:34.600000Z", "price_level": "63997.91", "new_quantity": "0"}, {"side": "bid", "event_time": "2026-09-24T12:00:34.600000Z", "price_level": "63998.00", "new_quantity": "0.06000000"}, {"side": "offer", "event_time": "2026-09-24T12:00:34.600000Z", "price_level": "63998.01", "new_quantity": "0.07000000"}]}]}
{"channel": "l2_data", "client_id": "", "timestamp": "2026-09-24T12:00:35.100000Z", "sequence_num": 128, "events": [{"type": "update", "product_id": "BTC-USD", "updates": [{"side": "offer", "event_time": "2026-09-24T12:00:35.100000Z", "price_level": "63998.01", "new_quantity": "0"}, {"side": "offer", "event_time": "2026-09-24T12:00:35.100000Z", "price_level": "63998.06", "new_quantity": "0"}, {"side": "bid", "event_time": "2026-09-24T12:00:35.100000Z", "price_level": "63998.10", "new_quantity": "0.06000000"}, {"side": "offer", "event_time": "2026-09-24T12:00:35.100000Z", "price_level": "63998.11", "new_quantity": "0.07000000"}]}]}
{"channel": "market_trades", "client_id": "", "timestamp": "2026-09-24T12:00:35.110000Z", "sequence_num": 129, "events": [{"type": "update", "trades": [{"trade_id": "1070", "product_id": "BTC-USD", "price": "63998.11", "size": "0.01500000", "side": "BUY", "time": "2026-09-24T12:00:35.110000Z"}]}]}
{"channel": "heartbeats", "client_id": "", "timestamp": "2026-09-24T12:00:35.130000Z", "sequence_num": 130, "events": [{"current_time": "2026-09-24T12:00:35.100000Z", "heartbeat_counter": 7}]}
{"channel": "l2_data", "client_id": "", "timestamp": "2026-09-24T12:00:35.600000Z", "sequence_num": 131, "events": [{"type": "update", "product_id": "BTC-USD", "updates": [{"side": "offer", "event_time": "2026-09-24T12:00:35.600000Z", "price_level": "63998.11", "new_quantity": "0"}, {"side": "bid", "event_time": "2026-09-24T12:00:35.600000Z", "price_level": "63998.20", "new_quantity": "0.06000000"}, {"side": "offer", "event_time": "2026-09-24T12:00:35.600000Z", "price_level": "63998.21", "new_quantity": "0.07000000"}]}]}
{"channel": "l2_data", "client_id": "", "timestamp": "2026-09-24T12:00:36.100000Z", "sequence_num": 132, "events": [{"type": "update", "product_id": "BTC-USD", "updates": [{"side": "offer", "event_time": "2026-09-24T12:00:36.100000Z", "price_level": "63998.21", "new_quantity": "0"}, {"side": "bid", "event_time": "2026-09-24T12:00:36.100000Z", "price_level": "63998.30", "new_quantity": "0.06000000"}, {"side": "offer", "event_time": "2026-09-24T12:00:36.100000Z", "price_level": "63998.31", "new_quantity": "0.07000000"}]}]}
{"channel": "market_trades", "client_id": "", "timestamp": "2026-09-24T12:00:36.110000Z", "sequence_num": 133, "events": [{"type": "update", "trades": [{"trade_id": "1072", "product_id": "BTC-USD", "price": "63998.31", "size": "0.01500000", "side": "BUY", "time": "2026-09-24T12:00:36.110000Z"}]}]}
{"channel": "ticker", "client_id": "", "timestamp": "2026-09-24T12:00:36.120000Z", "sequence_num": 134, "events": [{"type": "update", "tickers": [{"type": "ticker", "product_id": "BTC-USD", "price": "63998.30", "best_bid": "63998.30", "best_bid_quantity": "0.06", "best_ask": "63998.31", "best_ask_quantity": "0.07"}]}]}
{"channel": "l2_data", "client_id": "", "timestamp": "2026-09-24T12:00:36.600000Z", "sequence_num": 135, "events": [{"type": "update", "product_id": "BTC-USD", "updates": [{"side": "offer", "event_time": "2026-09-24T12:00:36.600000Z", "price_level": "63998.31", "new_quantity": "0"}, {"side": "offer", "event_time": "2026-09-24T12:00:36.600000Z", "price_level": "63998.36", "new_quantity": "0"}, {"side": "bid", "event_time": "2026-09-24T12:00:36.600000Z", "price_level": "63998.40", "new_quantity": "0.06000000"}, {"side": "offer", "event_time": "2026-09-24T12:00:36.600000Z", "price_level": "63998.41", "new_quantity": "0.07000000"}]}]}
{"channel": "l2_data", "client_id": "", "timestamp": "2026-09-24T12:00:37.100000Z", "sequence_num": 136, "events": [{"type": "update", "product_id": "BTC-USD", "updates": [{"side": "offer", "event_time": "2026-09-24T12:00:37.100000Z", "price_level": "63998.41", "new_quantity": "0"}, {"side": "bid", "event_time": "2026-09-24T12:00:37.100000Z", "price_level": "63998.50", "new_quantity": "0.06000000"}, {"side": "offer", "event_time": "2026-09-24T12:00:37.100000Z", "price_level": "63998.51", "new_quantity": "0.07000000"}]}]}
{"channel": "market_trades", "client_id": "", "timestamp": "2026-09-24T12:00:37.110000Z", "sequence_num": 137, "events": [{"type": "update", "trades": [{"trade_id": "1074", "product_id": "BTC-USD", "price": "63998.51", "size": "0.01500000", "side": "BUY", "time": "2026-09-24T12:00:37.110000Z"}]}]}
{"channel": "l2_data", "client_id": "", "timestamp": "2026-09-24T12:00:37.600000Z", "sequence_num": 138, "events": [{"type": "update", "product_id": "BTC-USD", "updates": [{"side": "offer", "event_time": "2026-09-24T12:00:37.600000Z", "price_level": "63998.51", "new_quantity": "0"}, {"side": "bid", "event_time": "2026-09-24T12:00:37.600000Z", "price_level": "63998.60", "new_quantity": "0.06000000"}, {"side": "offer", "event_time": "2026-09-24T12:00:37.600000Z", "price_level": "63998.61", "new_quantity": "0.07000000"}]}]}
{"channel": "l2_data", "client_id": "", "timestamp": "2026-09-24T12:00:38.100000Z", "sequence_num": 139, "events": [{"type": "update", "product_id": "BTC-USD", "updates": [{"side": "offer", "event_time": "2026-09-24T12:00:38.100000Z", "price_level": "63998.61", "new_quantity": "0"}, {"side": "offer", "event_time": "2026-09-24T12:00:38.100000Z", "price_level": "63998.66", "new_quantity": "0"}, {"side": "bid", "event_time": "2026-09-24T12:00:38.100000Z", "price_level": "63998.70", "new_quantity": "0.06000000"}, {"side": "offer", "event_time": "2026-09-24T12:00:38.100000Z", "price_level": "63998.71", "new_quantity": "0.07000000"}]}]}
{"channel": "market_trades", "client_id": "", "timestamp": "2026-09-24T12:00:38.110000Z", "sequence_num": 140, "events": [{"type": "update", "trades": [{"trade_id": "1076", "product_id": "BTC-USD", "price": "63998.71", "size": "0.01500000", "side": "BUY", "time": "2026-09-24T12:00:38.110000Z"}]}]}
{"channel": "ticker", "client_id": "", "timestamp": "2026-09-24T12:00:38.120000Z", "sequence_num": 141, "events": [{"type": "update", "tickers": [{"type": "ticker", "product_id": "BTC-USD", "price": "63998.70", "best_bid": "63998.70", "best_bid_quantity": "0.06", "best_ask": "63998.71", "best_ask_quantity": "0.07"}]}]}
{"channel": "l2_data", "client_id": "", "timestamp": "2026-09-24T12:00:38.600000Z", "sequence_num": 142, "events": [{"type": "update", "product_id": "BTC-USD", "updates": [{"side": "offer", "event_time": "2026-09-24T12:00:38.600000Z", "price_level": "63998.71", "new_quantity": "0"}, {"side": "bid", "event_time": "2026-09-24T12:00:38.600000Z", "price_level": "63998.80", "new_quantity": "0.06000000"}, {"side": "offer", "event_time": "2026-09-24T12:00:38.600000Z", "price_level": "63998.81", "new_quantity": "0.07000000"}]}]}
{"channel": "l2_data", "client_id": "", "timestamp": "2026-09-24T12:00:39.100000Z", "sequence_num": 143, "events": [{"type": "update", "product_id": "BTC-USD", "updates": [{"side": "offer", "event_time": "2026-09-24T12:00:39.100000Z", "price_level": "63998.81", "new_quantity": "0"}, {"side": "bid", "event_time": "2026-09-24T12:00:39.100000Z", "price_level": "63998.90", "new_quantity": "0.06000000"}, {"side": "offer", "event_time": "2026-09-24T12:00:39.100000Z", "price_level": "63998.91", "new_quantity": "0.07000000"}]}]}
{"channel": "market_trades", "client_id": "", "timestamp": "2026-09-24T12:00:39.110000Z", "sequence_num": 144, "events": [{"type": "update", "trades": [{"trade_id": "1078", "product_id": "BTC-USD", "price": "63998.91", "size": "0.01500000", "side": "BUY", "time": "2026-09-24T12:00:39.110000Z"}]}]}
{"channel": "l2_data", "client_id": "", "timestamp": "2026-09-24T12:00:39.600000Z", "sequence_num": 145, "events": [{"type": "update", "product_id": "BTC-USD", "updates": [{"side": "offer", "event_time": "2026-09-24T12:00:39.600000Z", "price_level": "63998.91", "new_quantity": "0"}, {"side": "offer", "event_time": "2026-09-24T12:00:39.600000Z", "price_level": "63998.96", "new_quantity": "0"}, {"side": "bid", "event_time": "2026-09-24T12:00:39.600000Z", "price_level": "63999.00", "new_quantity": "0.06000000"}, {"side": "offer", "event_time": "2026-09-24T12:00:39.600000Z", "price_level": "63999.01", "new_quantity": "0.07000000"}]}]}
{"channel": "l2_data", "client_id": "", "timestamp": "2026-09-24T12:00:40.100000Z", "sequence_num": 146, "events": [{"type": "update", "product_id": "BTC-USD", "updates": [{"side": "bid", "event_time": "2026-09-24T12:00:40.100000Z", "price_level": "63999.00", "new_quantity": "0.06000000"}, {"side": "offer", "event_time": "2026-09-24T12:00:40.100000Z", "price_level": "63999.01", "new_quantity": "0.07000000"}]}]}
{"channel": "market_trades", "client_id": "", "timestamp": "2026-09-24T12:00:40.110000Z", "sequence_num": 147, "events": [{"type": "update", "trades": [{"trade_id": "1080", "product_id": "BTC-USD", "price": "63999.01", "size": "0.01500000", "side": "BUY", "time": "2026-09-24T12:00:40.110000Z"}]}]}
{"channel": "ticker", "client_id": "", "timestamp": "2026-09-24T12:00:40.120000Z", "sequence_num": 148, "events": [{"type": "update", "tickers": [{"type": "ticker", "product_id": "BTC-USD", "price": "63999.00", "best_bid": "63999.00", "best_bid_quantity": "0.06", "best_ask": "63999.01", "best_ask_quantity": "0.07"}]}]}
{"channel": "heartbeats", "client_id": "", "timestamp": "2026-09-24T12:00:40.130000Z", "sequence_num": 149, "events": [{"current_time": "2026-09-24T12:00:40.100000Z", "heartbeat_counter": 8}]}
{"channel": "l2_data", "client_id": "", "timestamp": "2026-09-24T12:00:40.600000Z", "sequence_num": 150, "events": [{"type": "update", "product_id": "BTC-USD", "updates": [{"side": "bid", "event_time": "2026-09-24T12:00:40.600000Z", "price_level": "63999.00", "new_quantity": "0.06000000"}, {"side": "offer", "event_time": "2026-09-24T12:00:40.600000Z", "price_level": "63999.01", "new_quantity": "0.07000000"}]}]}
{"channel": "l2_data", "client_id": "", "timestamp": "2026-09-24T12:00:41.100000Z", "sequence_num": 151, "events": [{"type": "update", "product_id": "BTC-USD", "updates": [{"side": "bid", "event_time": "2026-09-24T12:00:41.100000Z", "price_level": "63999.00", "new_quantity": "0.06000000"}, {"side": "offer", "event_time": "2026-09-24T12:00:41.100000Z", "price_level": "63999.01", "new_quantity": "0.07000000"}]}]}
{"channel": "market_trades", "client_id": "", "timestamp": "2026-09-24T12:00:41.110000Z", "sequence_num": 152, "events": [{"type": "update", "trades": [{"trade_id": "1082", "product_id": "BTC-USD", "price": "63999.01", "size": "0.01500000", "side": "BUY", "time": "2026-09-24T12:00:41.110000Z"}]}]}
{"channel": "l2_data", "client_id": "", "timestamp": "2026-09-24T12:00:41.600000Z", "sequence_num": 153, "events": [{"type": "update", "product_id": "BTC-USD", "updates": [{"side": "bid", "event_time": "2026-09-24T12:00:41.600000Z", "price_level": "63999.00", "new_quantity": "0.06000000"}, {"side": "offer", "event_time": "2026-09-24T12:00:41.600000Z", "price_level": "63999.01", "new_quantity": "0.07000000"}]}]}
{"channel": "l2_data", "client_id": "", "timestamp": "2026-09-24T12:00:42.100000Z", "sequence_num": 154, "events": [{"type": "update", "product_id": "BTC-USD", "updates": [{"side": "bid", "event_time": "2026-09-24T12:00:42.100000Z", "price_level": "63999.00", "new_quantity": "0.06000000"}, {"side": "offer", "event_time": "2026-09-24T12:00:42.100000Z", "price_level": "63999.01", "new_quantity": "0.07000000"}]}]}
{"channel": "market_trades", "client_id": "", "timestamp": "2026-09-24T12:00:42.110000Z", "sequence_num": 155, "events": [{"type": "update", "trades": [{"trade_id": "1084", "product_id": "BTC-USD", "price": "63999.01", "size": "0.01500000", "side": "BUY", "time": "2026-09-24T12:00:42.110000Z"}]}]}
{"channel": "ticker", "client_id": "", "timestamp": "2026-09-24T12:00:42.120000Z", "sequence_num": 156, "events": [{"type": "update", "tickers": [{"type": "ticker", "product_id": "BTC-USD", "price": "63999.00", "best_bid": "63999.00", "best_bid_quantity": "0.06", "best_ask": "63999.01", "best_ask_quantity": "0.07"}]}]}
{"channel": "l2_data", "client_id": "", "timestamp": "2026-09-24T12:00:42.600000Z", "sequence_num": 157, "events": [{"type": "update", "product_id": "BTC-USD", "updates": [{"side": "bid", "event_time": "2026-09-24T12:00:42.600000Z", "price_level": "63999.00", "new_quantity": "0.06000000"}, {"side": "offer", "event_time": "2026-09-24T12:00:42.600000Z", "price_level": "63999.01", "new_quantity": "0.07000000"}]}]}
{"channel": "l2_data", "client_id": "", "timestamp": "2026-09-24T12:00:43.100000Z", "sequence_num": 158, "events": [{"type": "update", "product_id": "BTC-USD", "updates": [{"side": "bid", "event_time": "2026-09-24T12:00:43.100000Z", "price_level": "63999.00", "new_quantity": "0.06000000"}, {"side": "offer", "event_time": "2026-09-24T12:00:43.100000Z", "price_level": "63999.01", "new_quantity": "0.07000000"}]}]}
{"channel": "market_trades", "client_id": "", "timestamp": "2026-09-24T12:00:43.110000Z", "sequence_num": 159, "events": [{"type": "update", "trades": [{"trade_id": "1086", "product_id": "BTC-USD", "price": "63999.01", "size": "0.01500000", "side": "BUY", "time": "2026-09-24T12:00:43.110000Z"}]}]}
{"channel": "l2_data", "client_id": "", "timestamp": "2026-09-24T12:00:43.600000Z", "sequence_num": 160, "events": [{"type": "update", "product_id": "BTC-USD", "updates": [{"side": "bid", "event_time": "2026-09-24T12:00:43.600000Z", "price_level": "63999.00", "new_quantity": "0.06000000"}, {"side": "offer", "event_time": "2026-09-24T12:00:43.600000Z", "price_level": "63999.01", "new_quantity": "0.07000000"}]}]}
{"channel": "l2_data", "client_id": "", "timestamp": "2026-09-24T12:00:44.100000Z", "sequence_num": 161, "events": [{"type": "update", "product_id": "BTC-USD", "updates": [{"side": "bid", "event_time": "2026-09-24T12:00:44.100000Z", "price_level": "63999.00", "new_quantity": "0.06000000"}, {"side": "offer", "event_time": "2026-09-24T12:00:44.100000Z", "price_level": "63999.01", "new_quantity": "0.07000000"}]}]}
{"channel": "market_trades", "client_id": "", "timestamp": "2026-09-24T12:00:44.110000Z", "sequence_num": 162, "events": [{"type": "update", "trades": [{"trade_id": "1088", "product_id": "BTC-USD", "price": "63999.01", "size": "0.01500000", "side": "BUY", "time": "2026-09-24T12:00:44.110000Z"}]}]}
{"channel": "ticker", "client_id": "", "timestamp": "2026-09-24T12:00:44.120000Z", "sequence_num": 163, "events": [{"type": "update", "tickers": [{"type": "ticker", "product_id": "BTC-USD", "price": "63999.00", "best_bid": "63999.00", "best_bid_quantity": "0.06", "best_ask": "63999.01", "best_ask_quantity": "0.07"}]}]}
{"channel": "l2_data", "client_id": "", "timestamp": "2026-09-24T12:00:44.600000Z", "sequence_num": 164, "events": [{"type": "update", "product_id": "BTC-USD", "updates": [{"side": "bid", "event_time": "2026-09-24T12:00:44.600000Z", "price_level": "63999.00", "new_quantity": "0.06000000"}, {"side": "offer", "event_time": "2026-09-24T12:00:44.600000Z", "price_level": "63999.01", "new_quantity": "0.07000000"}]}]}
{"channel": "l2_data", "client_id": "", "timestamp": "2026-09-24T12:00:45.100000Z", "sequence_num": 165, "events": [{"type": "update", "product_id": "BTC-USD", "updates": [{"side": "bid", "event_time": "2026-09-24T12:00:45.100000Z", "price_level": "63999.00", "new_quantity": "0.06000000"}, {"side": "offer", "event_time": "2026-09-24T12:00:45.100000Z", "price_level": "63999.01", "new_quantity": "0.07000000"}]}]}
{"channel": "market_trades", "client_id": "", "timestamp": "2026-09-24T12:00:45.110000Z", "sequence_num": 166, "events": [{"type": "update", "trades": [{"trade_id": "1090", "product_id": "BTC-USD", "price": "63999.01", "size": "0.01500000", "side": "BUY", "time": "2026-09-24T12:00:45.110000Z"}]}]}
{"channel": "heartbeats", "client_id": "", "timestamp": "2026-09-24T12:00:45.130000Z", "sequence_num": 167, "events": [{"current_time": "2026-09-24T12:00:45.100000Z", "heartbeat_counter": 9}]}
{"channel": "l2_data", "client_id": "", "timestamp": "2026-09-24T12:00:45.600000Z", "sequence_num": 168, "events": [{"type": "update", "product_id": "BTC-USD", "updates": [{"side": "bid", "event_time": "2026-09-24T12:00:45.600000Z", "price_level": "63999.00", "new_quantity": "0.06000000"}, {"side": "offer", "event_time": "2026-09-24T12:00:45.600000Z", "price_level": "63999.01", "new_quantity": "0.07000000"}]}]}
{"channel": "l2_data", "client_id": "", "timestamp": "2026-09-24T12:00:46.100000Z", "sequence_num": 169, "events": [{"type": "update", "product_id": "BTC-USD", "updates": [{"side": "bid", "event_time": "2026-09-24T12:00:46.100000Z", "price_level": "63999.00", "new_quantity": "0.06000000"}, {"side": "offer", "event_time": "2026-09-24T12:00:46.100000Z", "price_level": "63999.01", "new_quantity": "0.07000000"}]}]}
{"channel": "market_trades", "client_id": "", "timestamp": "2026-09-24T12:00:46.110000Z", "sequence_num": 170, "events": [{"type": "update", "trades": [{"trade_id": "1092", "product_id": "BTC-USD", "price": "63999.01", "size": "0.01500000", "side": "BUY", "time": "2026-09-24T12:00:46.110000Z"}]}]}
{"channel": "ticker", "client_id": "", "timestamp": "2026-09-24T12:00:46.120000Z", "sequence_num": 171, "events": [{"type": "update", "tickers": [{"type": "ticker", "product_id": "BTC-USD", "price": "63999.00", "best_bid": "63999.00", "best_bid_quantity": "0.06", "best_ask": "63999.01", "best_ask_quantity": "0.07"}]}]}
{"channel": "l2_data", "client_id": "", "timestamp": "2026-09-24T12:00:46.600000Z", "sequence_num": 172, "events": [{"type": "update", "product_id": "BTC-USD", "updates": [{"side": "bid", "event_time": "2026-09-24T12:00:46.600000Z", "price_level": "63999.00", "new_quantity": "0.06000000"}, {"side": "offer", "event_time": "2026-09-24T12:00:46.600000Z", "price_level": "63999.01", "new_quantity": "0.07000000"}]}]}
{"channel": "l2_data", "client_id": "", "timestamp": "2026-09-24T12:00:47.100000Z", "sequence_num": 173, "events": [{"type": "update", "product_id": "BTC-USD", "updates": [{"side": "bid", "event_time": "2026-09-24T12:00:47.100000Z", "price_level": "63999.00", "new_quantity": "0.06000000"}, {"side": "offer", "event_time": "2026-09-24T12:00:47.100000Z", "price_level": "63999.01", "new_quantity": "0.07000000"}]}]}
{"channel": "market_trades", "client_id": "", "timestamp": "2026-09-24T12:00:47.110000Z", "sequence_num": 174, "events": [{"type": "update", "trades": [{"trade_id": "1094", "product_id": "BTC-USD", "price": "63999.01", "size": "0.01500000", "side": "BUY", "time": "2026-09-24T12:00:47.110000Z"}]}]}
{"channel": "l2_data", "client_id": "", "timestamp": "2026-09-24T12:00:47.600000Z", "sequence_num": 175, "events": [{"type": "update", "product_id": "BTC-USD", "updates": [{"side": "bid", "event_time": "2026-09-24T12:00:47.600000Z", "price_level": "63999.00", "new_quantity": "0.06000000"}, {"side": "offer", "event_time": "2026-09-24T12:00:47.600000Z", "price_level": "63999.01", "new_quantity": "0.07000000"}]}]}
{"channel": "l2_data", "client_id": "", "timestamp": "2026-09-24T12:00:48.100000Z", "sequence_num": 176, "events": [{"type": "update", "product_id": "BTC-USD", "updates": [{"side": "bid", "event_time": "2026-09-24T12:00:48.100000Z", "price_level": "63999.00", "new_quantity": "0.06000000"}, {"side": "offer", "event_time": "2026-09-24T12:00:48.100000Z", "price_level": "63999.01", "new_quantity": "0.07000000"}]}]}
{"channel": "market_trades", "client_id": "", "timestamp": "2026-09-24T12:00:48.110000Z", "sequence_num": 177, "events": [{"type": "update", "trades": [{"trade_id": "1096", "product_id": "BTC-USD", "price": "63999.01", "size": "0.01500000", "side": "BUY", "time": "2026-09-24T12:00:48.110000Z"}]}]}
{"channel": "ticker", "client_id": "", "timestamp": "2026-09-24T12:00:48.120000Z", "sequence_num": 178, "events": [{"type": "update", "tickers": [{"type": "ticker", "product_id": "BTC-USD", "price": "63999.00", "best_bid": "63999.00", "best_bid_quantity": "0.06", "best_ask": "63999.01", "best_ask_quantity": "0.07"}]}]}
{"channel": "l2_data", "client_id": "", "timestamp": "2026-09-24T12:00:48.600000Z", "sequence_num": 179, "events": [{"type": "update", "product_id": "BTC-USD", "updates": [{"side": "bid", "event_time": "2026-09-24T12:00:48.600000Z", "price_level": "63999.00", "new_quantity": "0.06000000"}, {"side": "offer", "event_time": "2026-09-24T12:00:48.600000Z", "price_level": "63999.01", "new_quantity": "0.07000000"}]}]}
{"channel": "l2_data", "client_id": "", "timestamp": "2026-09-24T12:00:49.100000Z", "sequence_num": 180, "events": [{"type": "update", "product_id": "BTC-USD", "updates": [{"side": "bid", "event_time": "2026-09-24T12:00:49.100000Z", "price_level": "63999.00", "new_quantity": "0.06000000"}, {"side": "offer", "event_time": "2026-09-24T12:00:49.100000Z", "price_level": "63999.01", "new_quantity": "0.07000000"}]}]}
{"channel": "market_trades", "client_id": "", "timestamp": "2026-09-24T12:00:49.110000Z", "sequence_num": 181, "events": [{"type": "update", "trades": [{"trade_id": "1098", "product_id": "BTC-USD", "price": "63999.01", "size": "0.01500000", "side": "BUY", "time": "2026-09-24T12:00:49.110000Z"}]}]}
{"channel": "l2_data", "client_id": "", "timestamp": "2026-09-24T12:00:49.600000Z", "sequence_num": 182, "events": [{"type": "update", "product_id": "BTC-USD", "updates": [{"side": "bid", "event_time": "2026-09-24T12:00:49.600000Z", "price_level": "63999.00", "new_quantity": "0.06000000"}, {"side": "offer", "event_time": "2026-09-24T12:00:49.600000Z", "price_level": "63999.01", "new_quantity": "0.07000000"}]}]}
{"channel": "l2_data", "client_id": "", "timestamp": "2026-09-24T12:00:50.100000Z", "sequence_num": 183, "events": [{"type": "update", "product_id": "BTC-USD", "updates": [{"side": "bid", "event_time": "2026-09-24T12:00:50.100000Z", "price_level": "63999.00", "new_quantity": "0.06000000"}, {"side": "offer", "event_time": "2026-09-24T12:00:50.100000Z", "price_level": "63999.01", "new_quantity": "0.07000000"}]}]}
{"channel": "market_trades", "client_id": "", "timestamp": "2026-09-24T12:00:50.110000Z", "sequence_num": 184, "events": [{"type": "update", "trades": [{"trade_id": "1100", "product_id": "BTC-USD", "price": "63999.01", "size": "0.01500000", "side": "BUY", "time": "2026-09-24T12:00:50.110000Z"}]}]}
{"channel": "ticker", "client_id": "", "timestamp": "2026-09-24T12:00:50.120000Z", "sequence_num": 185, "events": [{"type": "update", "tickers": [{"type": "ticker", "product_id": "BTC-USD", "price": "63999.00", "best_bid": "63999.00", "best_bid_quantity": "0.06", "best_ask": "63999.01", "best_ask_quantity": "0.07"}]}]}
{"channel": "heartbeats", "client_id": "", "timestamp": "2026-09-24T12:00:50.130000Z", "sequence_num": 186, "events": [{"current_time": "2026-09-24T12:00:50.100000Z", "heartbeat_counter": 10}]}
{"channel": "l2_data", "client_id": "", "timestamp": "2026-09-24T12:00:50.600000Z", "sequence_num": 187, "events": [{"type": "update", "product_id": "BTC-USD", "updates": [{"side": "bid", "event_time": "2026-09-24T12:00:50.600000Z", "price_level": "63999.00", "new_quantity": "0.06000000"}, {"side": "offer", "event_time": "2026-09-24T12:00:50.600000Z", "price_level": "63999.01", "new_quantity": "0.07000000"}]}]}
{"channel": "l2_data", "client_id": "", "timestamp": "2026-09-24T12:00:51.100000Z", "sequence_num": 188, "events": [{"type": "update", "product_id": "BTC-USD", "updates": [{"side": "bid", "event_time": "2026-09-24T12:00:51.100000Z", "price_level": "63999.00", "new_quantity": "0.06000000"}, {"side": "offer", "event_time": "2026-09-24T12:00:51.100000Z", "price_level": "63999.01", "new_quantity": "0.07000000"}]}]}
{"channel": "market_trades", "client_id": "", "timestamp": "2026-09-24T12:00:51.110000Z", "sequence_num": 189, "events": [{"type": "update", "trades": [{"trade_id": "1102", "product_id": "BTC-USD", "price": "63999.01", "size": "0.01500000", "side": "BUY", "time": "2026-09-24T12:00:51.110000Z"}]}]}
{"channel": "l2_data", "client_id": "", "timestamp": "2026-09-24T12:00:51.600000Z", "sequence_num": 190, "events": [{"type": "update", "product_id": "BTC-USD", "updates": [{"side": "bid", "event_time": "2026-09-24T12:00:51.600000Z", "price_level": "63999.00", "new_quantity": "0.06000000"}, {"side": "offer", "event_time": "2026-09-24T12:00:51.600000Z", "price_level": "63999.01", "new_quantity": "0.07000000"}]}]}
{"channel": "l2_data", "client_id": "", "timestamp": "2026-09-24T12:00:52.100000Z", "sequence_num": 191, "events": [{"type": "update", "product_id": "BTC-USD", "updates": [{"side": "bid", "event_time": "2026-09-24T12:00:52.100000Z", "price_level": "63999.00", "new_quantity": "0.06000000"}, {"side": "offer", "event_time": "2026-09-24T12:00:52.100000Z", "price_level": "63999.01", "new_quantity": "0.07000000"}]}]}
{"channel": "market_trades", "client_id": "", "timestamp": "2026-09-24T12:00:52.110000Z", "sequence_num": 192, "events": [{"type": "update", "trades": [{"trade_id": "1104", "product_id": "BTC-USD", "price": "63999.01", "size": "0.01500000", "side": "BUY", "time": "2026-09-24T12:00:52.110000Z"}]}]}
{"channel": "ticker", "client_id": "", "timestamp": "2026-09-24T12:00:52.120000Z", "sequence_num": 193, "events": [{"type": "update", "tickers": [{"type": "ticker", "product_id": "BTC-USD", "price": "63999.00", "best_bid": "63999.00", "best_bid_quantity": "0.06", "best_ask": "63999.01", "best_ask_quantity": "0.07"}]}]}
{"channel": "l2_data", "client_id": "", "timestamp": "2026-09-24T12:00:52.600000Z", "sequence_num": 194, "events": [{"type": "update", "product_id": "BTC-USD", "updates": [{"side": "bid", "event_time": "2026-09-24T12:00:52.600000Z", "price_level": "63999.00", "new_quantity": "0.06000000"}, {"side": "offer", "event_time": "2026-09-24T12:00:52.600000Z", "price_level": "63999.01", "new_quantity": "0.07000000"}]}]}
{"channel": "l2_data", "client_id": "", "timestamp": "2026-09-24T12:00:53.100000Z", "sequence_num": 195, "events": [{"type": "update", "product_id": "BTC-USD", "updates": [{"side": "bid", "event_time": "2026-09-24T12:00:53.100000Z", "price_level": "63999.00", "new_quantity": "0.06000000"}, {"side": "offer", "event_time": "2026-09-24T12:00:53.100000Z", "price_level": "63999.01", "new_quantity": "0.07000000"}]}]}
{"channel": "market_trades", "client_id": "", "timestamp": "2026-09-24T12:00:53.110000Z", "sequence_num": 196, "events": [{"type": "update", "trades": [{"trade_id": "1106", "product_id": "BTC-USD", "price": "63999.01", "size": "0.01500000", "side": "BUY", "time": "2026-09-24T12:00:53.110000Z"}]}]}
{"channel": "l2_data", "client_id": "", "timestamp": "2026-09-24T12:00:53.600000Z", "sequence_num": 197, "events": [{"type": "update", "product_id": "BTC-USD", "updates": [{"side": "bid", "event_time": "2026-09-24T12:00:53.600000Z", "price_level": "63999.00", "new_quantity": "0.06000000"}, {"side": "offer", "event_time": "2026-09-24T12:00:53.600000Z", "price_level": "63999.01", "new_quantity": "0.07000000"}]}]}
{"channel": "l2_data", "client_id": "", "timestamp": "2026-09-24T12:00:54.100000Z", "sequence_num": 198, "events": [{"type": "update", "product_id": "BTC-USD", "updates": [{"side": "bid", "event_time": "2026-09-24T12:00:54.100000Z", "price_level": "63999.00", "new_quantity": "0.06000000"}, {"side": "offer", "event_time": "2026-09-24T12:00:54.100000Z", "price_level": "63999.01", "new_quantity": "0.07000000"}]}]}
{"channel": "market_trades", "client_id": "", "timestamp": "2026-09-24T12:00:54.110000Z", "sequence_num": 199, "events": [{"type": "update", "trades": [{"trade_id": "1108", "product_id": "BTC-USD", "price": "63999.01", "size": "0.01500000", "side": "BUY", "time": "2026-09-24T12:00:54.110000Z"}]}]}
{"channel": "ticker", "client_id": "", "timestamp": "2026-09-24T12:00:54.120000Z", "sequence_num": 200, "events": [{"type": "update", "tickers": [{"type": "ticker", "product_id": "BTC-USD", "price": "63999.00", "best_bid": "63999.00", "best_bid_quantity": "0.06", "best_ask": "63999.01", "best_ask_quantity": "0.07"}]}]}
{"channel": "l2_data", "client_id": "", "timestamp": "2026-09-24T12:00:54.600000Z", "sequence_num": 201, "events": [{"type": "update", "product_id": "BTC-USD", "updates": [{"side": "bid", "event_time": "2026-09-24T12:00:54.600000Z", "price_level": "63999.00", "new_quantity": "0.06000000"}, {"side": "offer", "event_time": "2026-09-24T12:00:54.600000Z", "price_level": "63999.01", "new_quantity": "0.07000000"}]}]}
{"channel": "l2_data", "client_id": "", "timestamp": "2026-09-24T12:00:55.100000Z", "sequence_num": 202, "events": [{"type": "update", "product_id": "BTC-USD", "updates": [{"side": "bid", "event_time": "2026-09-24T12:00:55.100000Z", "price_level": "63999.00", "new_quantity": "0.06000000"}, {"side": "offer", "event_time": "2026-09-24T12:00:55.100000Z", "price_level": "63999.01", "new_quantity": "0.07000000"}]}]}
{"channel": "market_trades", "client_id": "", "timestamp": "2026-09-24T12:00:55.110000Z", "sequence_num": 203, "events": [{"type": "update", "trades": [{"trade_id": "1110", "product_id": "BTC-USD", "price": "63999.01", "size": "0.01500000", "side": "BUY", "time": "2026-09-24T12:00:55.110000Z"}]}]}
{"channel": "heartbeats", "client_id": "", "timestamp": "2026-09-24T12:00:55.130000Z", "sequence_num": 204, "events": [{"current_time": "2026-09-24T12:00:55.100000Z", "heartbeat_counter": 11}]}
{"channel": "l2_data", "client_id": "", "timestamp": "2026-09-24T12:00:55.600000Z", "sequence_num": 205, "events": [{"type": "update", "product_id": "BTC-USD", "updates": [{"side": "bid", "event_time": "2026-09-24T12:00:55.600000Z", "price_level": "63999.00", "new_quantity": "0.06000000"}, {"side": "offer", "event_time": "2026-09-24T12:00:55.600000Z", "price_level": "63999.01", "new_quantity": "0.07000000"}]}]}
{"channel": "l2_data", "client_id": "", "timestamp": "2026-09-24T12:00:56.100000Z", "sequence_num": 206, "events": [{"type": "update", "product_id": "BTC-USD", "updates": [{"side": "bid", "event_time": "2026-09-24T12:00:56.100000Z", "price_level": "63999.00", "new_quantity": "0.06000000"}, {"side": "offer", "event_time": "2026-09-24T12:00:56.100000Z", "price_level": "63999.01", "new_quantity": "0.07000000"}]}]}
{"channel": "market_trades", "client_id": "", "timestamp": "2026-09-24T12:00:56.110000Z", "sequence_num": 207, "events": [{"type": "update", "trades": [{"trade_id": "1112", "product_id": "BTC-USD", "price": "63999.01", "size": "0.01500000", "side": "BUY", "time": "2026-09-24T12:00:56.110000Z"}]}]}
{"channel": "ticker", "client_id": "", "timestamp": "2026-09-24T12:00:56.120000Z", "sequence_num": 208, "events": [{"type": "update", "tickers": [{"type": "ticker", "product_id": "BTC-USD", "price": "63999.00", "best_bid": "63999.00", "best_bid_quantity": "0.06", "best_ask": "63999.01", "best_ask_quantity": "0.07"}]}]}
{"channel": "l2_data", "client_id": "", "timestamp": "2026-09-24T12:00:56.600000Z", "sequence_num": 209, "events": [{"type": "update", "product_id": "BTC-USD", "updates": [{"side": "bid", "event_time": "2026-09-24T12:00:56.600000Z", "price_level": "63999.00", "new_quantity": "0.06000000"}, {"side": "offer", "event_time": "2026-09-24T12:00:56.600000Z", "price_level": "63999.01", "new_quantity": "0.07000000"}]}]}
{"channel": "l2_data", "client_id": "", "timestamp": "2026-09-24T12:00:57.100000Z", "sequence_num": 210, "events": [{"type": "update", "product_id": "BTC-USD", "updates": [{"side": "bid", "event_time": "2026-09-24T12:00:57.100000Z", "price_level": "63999.00", "new_quantity": "0.06000000"}, {"side": "offer", "event_time": "2026-09-24T12:00:57.100000Z", "price_level": "63999.01", "new_quantity": "0.07000000"}]}]}
{"channel": "market_trades", "client_id": "", "timestamp": "2026-09-24T12:00:57.110000Z", "sequence_num": 211, "events": [{"type": "update", "trades": [{"trade_id": "1114", "product_id": "BTC-USD", "price": "63999.01", "size": "0.01500000", "side": "BUY", "time": "2026-09-24T12:00:57.110000Z"}]}]}
{"channel": "l2_data", "client_id": "", "timestamp": "2026-09-24T12:00:57.600000Z", "sequence_num": 212, "events": [{"type": "update", "product_id": "BTC-USD", "updates": [{"side": "bid", "event_time": "2026-09-24T12:00:57.600000Z", "price_level": "63999.00", "new_quantity": "0.06000000"}, {"side": "offer", "event_time": "2026-09-24T12:00:57.600000Z", "price_level": "63999.01", "new_quantity": "0.07000000"}]}]}
{"channel": "l2_data", "client_id": "", "timestamp": "2026-09-24T12:00:58.100000Z", "sequence_num": 213, "events": [{"type": "update", "product_id": "BTC-USD", "updates": [{"side": "bid", "event_time": "2026-09-24T12:00:58.100000Z", "price_level": "63999.00", "new_quantity": "0.06000000"}, {"side": "offer", "event_time": "2026-09-24T12:00:58.100000Z", "price_level": "63999.01", "new_quantity": "0.07000000"}]}]}
{"channel": "market_trades", "client_id": "", "timestamp": "2026-09-24T12:00:58.110000Z", "sequence_num": 214, "events": [{"type": "update", "trades": [{"trade_id": "1116", "product_id": "BTC-USD", "price": "63999.01", "size": "0.01500000", "side": "BUY", "time": "2026-09-24T12:00:58.110000Z"}]}]}
{"channel": "ticker", "client_id": "", "timestamp": "2026-09-24T12:00:58.120000Z", "sequence_num": 215, "events": [{"type": "update", "tickers": [{"type": "ticker", "product_id": "BTC-USD", "price": "63999.00", "best_bid": "63999.00", "best_bid_quantity": "0.06", "best_ask": "63999.01", "best_ask_quantity": "0.07"}]}]}
{"channel": "l2_data", "client_id": "", "timestamp": "2026-09-24T12:00:58.600000Z", "sequence_num": 216, "events": [{"type": "update", "product_id": "BTC-USD", "updates": [{"side": "bid", "event_time": "2026-09-24T12:00:58.600000Z", "price_level": "63999.00", "new_quantity": "0.06000000"}, {"side": "offer", "event_time": "2026-09-24T12:00:58.600000Z", "price_level": "63999.01", "new_quantity": "0.07000000"}]}]}
{"channel": "l2_data", "client_id": "", "timestamp": "2026-09-24T12:00:59.100000Z", "sequence_num": 217, "events": [{"type": "update", "product_id": "BTC-USD", "updates": [{"side": "bid", "event_time": "2026-09-24T12:00:59.100000Z", "price_level": "63999.00", "new_quantity": "0.06000000"}, {"side": "offer", "event_time": "2026-09-24T12:00:59.100000Z", "price_level": "63999.01", "new_quantity": "0.07000000"}]}]}
{"channel": "market_trades", "client_id": "", "timestamp": "2026-09-24T12:00:59.110000Z", "sequence_num": 218, "events": [{"type": "update", "trades": [{"trade_id": "1118", "product_id": "BTC-USD", "price": "63999.01", "size": "0.01500000", "side": "BUY", "time": "2026-09-24T12:00:59.110000Z"}]}]}
{"channel": "l2_data", "client_id": "", "timestamp": "2026-09-24T12:00:59.600000Z", "sequence_num": 219, "events": [{"type": "update", "product_id": "BTC-USD", "updates": [{"side": "bid", "event_time": "2026-09-24T12:00:59.600000Z", "price_level": "63999.00", "new_quantity": "0.06000000"}, {"side": "offer", "event_time": "2026-09-24T12:00:59.600000Z", "price_level": "63999.01", "new_quantity": "0.07000000"}]}]}
{"channel": "l2_data", "client_id": "", "timestamp": "2026-09-24T12:01:00.100000Z", "sequence_num": 220, "events": [{"type": "update", "product_id": "BTC-USD", "updates": [{"side": "bid", "event_time": "2026-09-24T12:01:00.100000Z", "price_level": "63999.00", "new_quantity": "0.06000000"}, {"side": "offer", "event_time": "2026-09-24T12:01:00.100000Z", "price_level": "63999.01", "new_quantity": "0.07000000"}]}]}
{"channel": "market_trades", "client_id": "", "timestamp": "2026-09-24T12:01:00.110000Z", "sequence_num": 221, "events": [{"type": "update", "trades": [{"trade_id": "1120", "product_id": "BTC-USD", "price": "63999.01", "size": "0.01500000", "side": "BUY", "time": "2026-09-24T12:01:00.110000Z"}]}]}
{"channel": "ticker", "client_id": "", "timestamp": "2026-09-24T12:01:00.120000Z", "sequence_num": 222, "events": [{"type": "update", "tickers": [{"type": "ticker", "product_id": "BTC-USD", "price": "63999.00", "best_bid": "63999.00", "best_bid_quantity": "0.06", "best_ask": "63999.01", "best_ask_quantity": "0.07"}]}]}
{"channel": "heartbeats", "client_id": "", "timestamp": "2026-09-24T12:01:00.130000Z", "sequence_num": 223, "events": [{"current_time": "2026-09-24T12:01:00.100000Z", "heartbeat_counter": 12}]}
